Workbook

Sheet 销售计划（销售前）
A1: 项目
A2: 销售计划（销售前）
R3: 0-30天新品期 | AV3: 31-120天热销期 | EH3: 121-180天清货期
A4: SKC | B4: 上架时间 | C4: 已上架天数 | D4: 销售周期标签 | E4: 库存 | F4: 可售周期 | G4: 累计销量 | H4: 达成比例 | I4: 昨日销售达成情况 | J4: 7天销售达成情况 | K4: 30天销售达成情况 | L4: 订货数量 | M4: 昨日计划销售数量 | N4: 今日计划销售数量 | O4: 某天 | P4: 某一天应销售数量 | Q4: 距离已上架数量（）天 | R4: 1 | S4: 2 | T4: 3 | U4: 4 | V4: 5 | W4: 6 | X4: 7 | Y4: 8 | Z4: 9 | AA4: 10 | AB4: 11 | AC4: 12 | AD4: 13 | AE4: 14 | AF4: 15 | AG4: 16 | AH4: 17 | AI4: 18 | AJ4: 19 | AK4: 20 | AL4: 21 | AM4: 22 | AN4: 23 | AO4: 24 | AP4: 25 | AQ4: 26 | AR4: 27 | AS4: 28 | AT4: 29 | AU4: 30 | AV4: 31 | AW4: 32 | AX4: 33 | AY4: 34 | AZ4: 35 | BA4: 36 | BB4: 37 | BC4: 38 | BD4: 39 | BE4: 40 | BF4: 41 | BG4: 42 | BH4: 43 | BI4: 44 | BJ4: 45 | BK4: 46 | BL4: 47 | BM4: 48 | BN4: 49 | BO4: 50 | BP4: 51 | BQ4: 52 | BR4: 53 | BS4: 54 | BT4: 55 | BU4: 56 | BV4: 57 | BW4: 58 | BX4: 59 | BY4: 60 | BZ4: 61 | CA4: 62 | CB4: 63 | CC4: 64 | CD4: 65 | CE4: 66 | CF4: 67 | CG4: 68 | CH4: 69 | CI4: 70 | CJ4: 71 | CK4: 72 | CL4: 73 | CM4: 74 | CN4: 75 | CO4: 76 | CP4: 77 | CQ4: 78 | CR4: 79 | CS4: 80 | CT4: 81 | CU4: 82 | CV4: 83 | CW4: 84 | CX4: 85 | CY4: 86 | CZ4: 87 | DA4: 88 | DB4: 89 | DC4: 90 | DD4: 91 | DE4: 92 | DF4: 93 | DG4: 94 | DH4: 95 | DI4: 96 | DJ4: 97 | DK4: 98 | DL4: 99 | DM4: 100 | DN4: 101 | DO4: 102 | DP4: 103 | DQ4: 104 | DR4: 105 | DS4: 106 | DT4: 107 | DU4: 108 | DV4: 109 | DW4: 110 | DX4: 111 | DY4: 112 | DZ4: 113 | EA4: 114 | EB4: 115 | EC4: 116 | ED4: 117 | EE4: 118 | EF4: 119 | EG4: 120 | EH4: 121 | EI4: 122 | EJ4: 123 | EK4: 124 | EL4: 125 | EM4: 126 | EN4: 127 | EO4: 128 | EP4: 129 | EQ4: 130 | ER4: 131 | ES4: 132 | ET4: 133 | EU4: 134 | EV4: 135 | EW4: 136 | EX4: 137 | EY4: 138 | EZ4: 139 | FA4: 140 | FB4: 141 | FC4: 142 | FD4: 143 | FE4: 144 | FF4: 145 | FG4: 146 | FH4: 147 | FI4: 148 | FJ4: 149 | FK4: 150 | FL4: 151 | FM4: 152 | FN4: 153 | FO4: 154 | FP4: 155 | FQ4: 156 | FR4: 157 | FS4: 158 | FT4: 159 | FU4: 160 | FV4: 161 | FW4: 162 | FX4: 163 | FY4: 164 | FZ4: 165 | GA4: 166 | GB4: 167 | GC4: 168 | GD4: 169 | GE4: 170 | GF4: 171 | GG4: 172 | GH4: 173 | GI4: 174 | GJ4: 175 | GK4: 176 | GL4: 177 | GM4: 178 | GN4: 179 | GO4: 180
A5: ABCW011-1 | B5: 46062 | C5: =TODAY()-B5+1 -> 147 | D5: {=_xlfn.IFS(AND(TODAY()-B5<=30,TODAY()-B5>=0),"新品期",AND(TODAY()-B5>=31,TODAY()-B5<=120),"热销期",AND(TODAY()-B5>=121,TODAY()-B5<=180),"清货期",TODAY()-B5>180,"滞销")} -> 清货期 | H5: =G5/L5 -> 0 | J5: =SUM(INDEX(R5:GO5,C5-1):INDEX(R5:GO5,C5-7)) -> 194.44444 | L5: 5000 | M5: {=IF($C5>180,"0",INDEX($R5:$GO5,$C5-1))} -> 27.777778 | N5: {=IF($C5>180,"0",INDEX($R5:$GO5,$C5))} -> 27.777778 | O5: 46144 | P5: {=IFERROR(INDEX(R5:GO5,Q5),"/")} -> 30.555556 | Q5: =IF(O5-B5>0,O5-B5,"此时段未上架") -> 82 | R5: =$L5*80%/180 -> 22.222222 | S5: =$L5*80%/180 -> 22.222222 | T5: =$L5*80%/180 -> 22.222222 | U5: =$L5*80%/180 -> 22.222222 | V5: =$L5*80%/180 -> 22.222222 | W5: =$L5*80%/180 -> 22.222222 | X5: =$L5*80%/180 -> 22.222222 | Y5: =$L5*80%/180 -> 22.222222 | ... AU5: =$L5*80%/180 -> 22.222222 | AV5: =$L5*110%/180 -> 30.555556 | AW5: =$L5*110%/180 -> 30.555556 | AX5: =$L5*110%/180 -> 30.555556 | AY5: =$L5*110%/180 -> 30.555556 | AZ5: =$L5*110%/180 -> 30.555556 | BA5: =$L5*110%/180 -> 30.555556 | BB5: =$L5*110%/180 -> 30.555556 | BC5: =$L5*110%/180 -> 30.555556 | ... EG5: =$L5*110%/180 -> 30.555556 | EH5: =$L5*100%/180 -> 27.777778 | EI5: =$L5*100%/180 -> 27.777778 | EJ5: =$L5*100%/180 -> 27.777778 | EK5: =$L5*100%/180 -> 27.777778 | EL5: =$L5*100%/180 -> 27.777778 | EM5: =$L5*100%/180 -> 27.777778 | EN5: =$L5*100%/180 -> 27.777778 | EO5: =$L5*100%/180 -> 27.777778 | ... GO5: =$L5*100%/180 -> 27.777778
A6: ABAV085-3 | B6: 46134 | C6: =TODAY()-B6+1 -> 75 | D6: {=_xlfn.IFS(AND(TODAY()-B6<=30,TODAY()-B6>=0),"新品期",AND(TODAY()-B6>=31,TODAY()-B6<=120),"热销期",AND(TODAY()-B6>=121,TODAY()-B6<=180),"清货期",TODAY()-B6>180,"滞销")} -> 热销期 | H6: =G6/L6 -> 0 | J6: {=INDEX(R5:GO5,C5-7)} -> 27.777778 | L6: 3000 | M6: {=IF($C6>180,"0",INDEX($R6:$GO6,$C6-1))} -> 18.333333 | N6: {=IF(C6>180,"0",INDEX(R6:GO6,C6))} -> 18.333333 | O6: 46144 | P6: {=IFERROR(INDEX(R6:GO6,Q6),"/")} -> 13.333333 | Q6: =IF(O6-B6>0,O6-B6,"此时段未上架") -> 10 | R6: =$L6*80%/180 -> 13.333333 | S6: =$L6*80%/180 -> 13.333333 | T6: =$L6*80%/180 -> 13.333333 | U6: =$L6*80%/180 -> 13.333333 | V6: =$L6*80%/180 -> 13.333333 | W6: =$L6*80%/180 -> 13.333333 | X6: =$L6*80%/180 -> 13.333333 | Y6: =$L6*80%/180 -> 13.333333 | ... AU6: =$L6*80%/180 -> 13.333333 | AV6: =$L6*110%/180 -> 18.333333 | AW6: =$L6*110%/180 -> 18.333333 | AX6: =$L6*110%/180 -> 18.333333 | AY6: =$L6*110%/180 -> 18.333333 | AZ6: =$L6*110%/180 -> 18.333333 | BA6: =$L6*110%/180 -> 18.333333 | BB6: =$L6*110%/180 -> 18.333333 | BC6: =$L6*110%/180 -> 18.333333 | ... EG6: =$L6*110%/180 -> 18.333333 | EH6: =$L6*100%/180 -> 16.666667 | EI6: =$L6*100%/180 -> 16.666667 | EJ6: =$L6*100%/180 -> 16.666667 | EK6: =$L6*100%/180 -> 16.666667 | EL6: =$L6*100%/180 -> 16.666667 | EM6: =$L6*100%/180 -> 16.666667 | EN6: =$L6*100%/180 -> 16.666667 | EO6: =$L6*100%/180 -> 16.666667 | ... GO6: =$L6*100%/180 -> 16.666667
A7: ABPV009-6 | B7: 46170 | C7: =TODAY()-B7+1 -> 39 | D7: {=_xlfn.IFS(AND(TODAY()-B7<=30,TODAY()-B7>=0),"新品期",AND(TODAY()-B7>=31,TODAY()-B7<=120),"热销期",AND(TODAY()-B7>=121,TODAY()-B7<=180),"清货期",TODAY()-B7>180,"滞销")} -> 热销期 | H7: =G7/L7 -> 0 | L7: 1000 | M7: {=IF($C7>180,"0",INDEX($R7:$GO7,$C7-1))} -> 6.1111111 | N7: {=IF(C7>180,"0",INDEX(R7:GO7,C7))} -> 6.1111111 | O7: 46144 | P7: {=IFERROR(INDEX(R7:GO7,Q7),"/")} -> / | Q7: =IF(O7-B7>0,O7-B7,"此时段未上架") -> 此时段未上架 | R7: =$L7*80%/180 -> 4.4444444 | S7: =$L7*80%/180 -> 4.4444444 | T7: =$L7*80%/180 -> 4.4444444 | U7: =$L7*80%/180 -> 4.4444444 | V7: =$L7*80%/180 -> 4.4444444 | W7: =$L7*80%/180 -> 4.4444444 | X7: =$L7*80%/180 -> 4.4444444 | Y7: =$L7*80%/180 -> 4.4444444 | ... AU7: =$L7*80%/180 -> 4.4444444 | AV7: =$L7*110%/180 -> 6.1111111 | AW7: =$L7*110%/180 -> 6.1111111 | AX7: =$L7*110%/180 -> 6.1111111 | AY7: =$L7*110%/180 -> 6.1111111 | AZ7: =$L7*110%/180 -> 6.1111111 | BA7: =$L7*110%/180 -> 6.1111111 | BB7: =$L7*110%/180 -> 6.1111111 | BC7: =$L7*110%/180 -> 6.1111111 | ... EG7: =$L7*110%/180 -> 6.1111111 | EH7: =$L7*100%/180 -> 5.5555556 | EI7: =$L7*100%/180 -> 5.5555556 | EJ7: =$L7*100%/180 -> 5.5555556 | EK7: =$L7*100%/180 -> 5.5555556 | EL7: =$L7*100%/180 -> 5.5555556 | EM7: =$L7*100%/180 -> 5.5555556 | EN7: =$L7*100%/180 -> 5.5555556 | EO7: =$L7*100%/180 -> 5.5555556 | ... GO7: =$L7*100%/180 -> 5.5555556
A8: ABAV045-2 | B8: 45971 | C8: =TODAY()-B8+1 -> 238 | D8: {=_xlfn.IFS(AND(TODAY()-B8<=30,TODAY()-B8>=0),"新品期",AND(TODAY()-B8>=31,TODAY()-B8<=120),"热销期",AND(TODAY()-B8>=121,TODAY()-B8<=180),"清货期",TODAY()-B8>180,"滞销")} -> 滞销 | H8: =G8/L8 -> 0 | L8: 2000 | M8: {=IF($C8>180,"0",INDEX($R8:$GO8,$C8-1))} -> 0 | N8: {=IF(C8>180,"0",INDEX(R8:GO8,C8))} -> 0 | O8: 46144 | P8: {=IFERROR(INDEX(R8:GO8,Q8),"/")} -> 11.111111 | Q8: =IF(O8-B8>0,O8-B8,"此时段未上架") -> 173 | R8: =$L8*80%/180 -> 8.8888889 | S8: =$L8*80%/180 -> 8.8888889 | T8: =$L8*80%/180 -> 8.8888889 | U8: =$L8*80%/180 -> 8.8888889 | V8: =$L8*80%/180 -> 8.8888889 | W8: =$L8*80%/180 -> 8.8888889 | X8: =$L8*80%/180 -> 8.8888889 | Y8: =$L8*80%/180 -> 8.8888889 | ... AU8: =$L8*80%/180 -> 8.8888889 | AV8: =$L8*110%/180 -> 12.222222 | AW8: =$L8*110%/180 -> 12.222222 | AX8: =$L8*110%/180 -> 12.222222 | AY8: =$L8*110%/180 -> 12.222222 | AZ8: =$L8*110%/180 -> 12.222222 | BA8: =$L8*110%/180 -> 12.222222 | BB8: =$L8*110%/180 -> 12.222222 | BC8: =$L8*110%/180 -> 12.222222 | ... EG8: =$L8*110%/180 -> 12.222222 | EH8: =$L8*100%/180 -> 11.111111 | EI8: =$L8*100%/180 -> 11.111111 | EJ8: =$L8*100%/180 -> 11.111111 | EK8: =$L8*100%/180 -> 11.111111 | EL8: =$L8*100%/180 -> 11.111111 | EM8: =$L8*100%/180 -> 11.111111 | EN8: =$L8*100%/180 -> 11.111111 | EO8: =$L8*100%/180 -> 11.111111 | ... GO8: =$L8*100%/180 -> 11.111111
B9: 46185 | C9: =TODAY()-B9+1 -> 24 | D9: {=_xlfn.IFS(AND(TODAY()-B9<=30,TODAY()-B9>=0),"新品期",AND(TODAY()-B9>=31,TODAY()-B9<=120),"热销期",AND(TODAY()-B9>=121,TODAY()-B9<=180),"清货期",TODAY()-B9>180,"滞销")} -> 新品期 | H9: =G9/L9 -> 0 | L9: 1000 | M9: {=IF($C9>180,"0",INDEX($R9:$GO9,$C9-1))} -> 4.4444444 | N9: {=IF(C9>180,"0",INDEX(R9:GO9,C9))} -> 4.4444444 | O9: 46144 | P9: {=IFERROR(INDEX(R9:GO9,Q9),"/")} -> / | Q9: =IF(O9-B9>0,O9-B9,"此时段未上架") -> 此时段未上架 | R9: =$L9*80%/180 -> 4.4444444 | S9: =$L9*80%/180 -> 4.4444444 | T9: =$L9*80%/180 -> 4.4444444 | U9: =$L9*80%/180 -> 4.4444444 | V9: =$L9*80%/180 -> 4.4444444 | W9: =$L9*80%/180 -> 4.4444444 | X9: =$L9*80%/180 -> 4.4444444 | Y9: =$L9*80%/180 -> 4.4444444 | ... AU9: =$L9*80%/180 -> 4.4444444 | AV9: =$L9*110%/180 -> 6.1111111 | AW9: =$L9*110%/180 -> 6.1111111 | AX9: =$L9*110%/180 -> 6.1111111 | AY9: =$L9*110%/180 -> 6.1111111 | AZ9: =$L9*110%/180 -> 6.1111111 | BA9: =$L9*110%/180 -> 6.1111111 | BB9: =$L9*110%/180 -> 6.1111111 | BC9: =$L9*110%/180 -> 6.1111111 | ... EG9: =$L9*110%/180 -> 6.1111111 | EH9: =$L9*100%/180 -> 5.5555556 | EI9: =$L9*100%/180 -> 5.5555556 | EJ9: =$L9*100%/180 -> 5.5555556 | EK9: =$L9*100%/180 -> 5.5555556 | EL9: =$L9*100%/180 -> 5.5555556 | EM9: =$L9*100%/180 -> 5.5555556 | EN9: =$L9*100%/180 -> 5.5555556 | EO9: =$L9*100%/180 -> 5.5555556 | ... GO9: =$L9*100%/180 -> 5.5555556
C10: =TODAY()-B10 -> 46208 | H10: =G10/L10 -> #DIV/0! | M10: {=IF($C10>180,"0",INDEX($R10:$GO10,$C10-1))} -> 0 | N10: {=IF(C10>180,"0",INDEX(R10:GO10,C10))} -> 0 | O10: 46144 | P10: {=IFERROR(INDEX(R10:GO10,Q10),"/")} -> / | Q10: =IF(O10-B10>0,O10-B10,"此时段未上架") -> 46144 | R10: =$L10*80%/180 -> 0 | S10: =$L10*80%/180 -> 0 | T10: =$L10*80%/180 -> 0 | U10: =$L10*80%/180 -> 0 | V10: =$L10*80%/180 -> 0 | W10: =$L10*80%/180 -> 0 | X10: =$L10*80%/180 -> 0 | Y10: =$L10*80%/180 -> 0 | ... AU10: =$L10*80%/180 -> 0 | AV10: =$L10*110%/180 -> 0 | AW10: =$L10*110%/180 -> 0 | AX10: =$L10*110%/180 -> 0 | AY10: =$L10*110%/180 -> 0 | AZ10: =$L10*110%/180 -> 0 | BA10: =$L10*110%/180 -> 0 | BB10: =$L10*110%/180 -> 0 | BC10: =$L10*110%/180 -> 0 | ... EG10: =$L10*110%/180 -> 0 | EH10: =$L10*100%/180 -> 0 | EI10: =$L10*100%/180 -> 0 | EJ10: =$L10*100%/180 -> 0 | EK10: =$L10*100%/180 -> 0 | EL10: =$L10*100%/180 -> 0 | EM10: =$L10*100%/180 -> 0 | EN10: =$L10*100%/180 -> 0 | EO10: =$L10*100%/180 -> 0 | ... GO10: =$L10*100%/180 -> 0
C11: =TODAY()-B11 -> 46208 | H11: =G11/L11 -> #DIV/0! | M11: {=IF($C11>180,"0",INDEX($R11:$GO11,$C11-1))} -> 0 | N11: {=IF(C11>180,"0",INDEX(R11:GO11,C11))} -> 0 | O11: 46144 | P11: {=IFERROR(INDEX(R11:GO11,Q11),"/")} -> / | Q11: =IF(O11-B11>0,O11-B11,"此时段未上架") -> 46144 | R11: =$L11*80%/180 -> 0 | S11: =$L11*80%/180 -> 0 | T11: =$L11*80%/180 -> 0 | U11: =$L11*80%/180 -> 0 | V11: =$L11*80%/180 -> 0 | W11: =$L11*80%/180 -> 0 | X11: =$L11*80%/180 -> 0 | Y11: =$L11*80%/180 -> 0 | ... AU11: =$L11*80%/180 -> 0 | AV11: =$L11*110%/180 -> 0 | AW11: =$L11*110%/180 -> 0 | AX11: =$L11*110%/180 -> 0 | AY11: =$L11*110%/180 -> 0 | AZ11: =$L11*110%/180 -> 0 | BA11: =$L11*110%/180 -> 0 | BB11: =$L11*110%/180 -> 0 | BC11: =$L11*110%/180 -> 0 | ... EG11: =$L11*110%/180 -> 0 | EH11: =$L11*100%/180 -> 0 | EI11: =$L11*100%/180 -> 0 | EJ11: =$L11*100%/180 -> 0 | EK11: =$L11*100%/180 -> 0 | EL11: =$L11*100%/180 -> 0 | EM11: =$L11*100%/180 -> 0 | EN11: =$L11*100%/180 -> 0 | EO11: =$L11*100%/180 -> 0 | ... GO11: =$L11*100%/180 -> 0
C12: =TODAY()-B12 -> 46208 | H12: =G12/L12 -> #DIV/0! | M12: {=IF($C12>180,"0",INDEX($R12:$GO12,$C12-1))} -> 0 | N12: {=IF(C12>180,"0",INDEX(R12:GO12,C12))} -> 0 | O12: 46144 | P12: {=IFERROR(INDEX(R12:GO12,Q12),"/")} -> / | Q12: =IF(O12-B12>0,O12-B12,"此时段未上架") -> 46144 | R12: =$L12*80%/180 -> 0 | S12: =$L12*80%/180 -> 0 | T12: =$L12*80%/180 -> 0 | U12: =$L12*80%/180 -> 0 | V12: =$L12*80%/180 -> 0 | W12: =$L12*80%/180 -> 0 | X12: =$L12*80%/180 -> 0 | Y12: =$L12*80%/180 -> 0 | ... AU12: =$L12*80%/180 -> 0 | AV12: =$L12*110%/180 -> 0 | AW12: =$L12*110%/180 -> 0 | AX12: =$L12*110%/180 -> 0 | AY12: =$L12*110%/180 -> 0 | AZ12: =$L12*110%/180 -> 0 | BA12: =$L12*110%/180 -> 0 | BB12: =$L12*110%/180 -> 0 | BC12: =$L12*110%/180 -> 0 | ... EG12: =$L12*110%/180 -> 0 | EH12: =$L12*100%/180 -> 0 | EI12: =$L12*100%/180 -> 0 | EJ12: =$L12*100%/180 -> 0 | EK12: =$L12*100%/180 -> 0 | EL12: =$L12*100%/180 -> 0 | EM12: =$L12*100%/180 -> 0 | EN12: =$L12*100%/180 -> 0 | EO12: =$L12*100%/180 -> 0 | ... GO12: =$L12*100%/180 -> 0

Sheet 销售计划（销售后）
A1: 项目
A2: 销售计划（销售后）
P3: 0-30天新品期 | AT3: 31-120天热销期 | EF3: 121-180天清货期
A4: SKC | B4: 上架时间 | C4: 已上架天数 | D4: 销售周期标签 | E4: 库存 | F4: 可售周期 | G4: 累计销量 | H4: 达成比例 | I4: 昨日销售达成情况 | J4: 7天销售达成情况 | K4: 30天销售达成情况 | L4: 订货数量 | M4: 昨日实际销售 | N4: 今日计划销售数量 | P4: 1 | Q4: 2 | R4: 3 | S4: 4 | T4: 5 | U4: 6 | V4: 7 | W4: 8 | X4: 9 | Y4: 10 | Z4: 11 | AA4: 12 | AB4: 13 | AC4: 14 | AD4: 15 | AE4: 16 | AF4: 17 | AG4: 18 | AH4: 19 | AI4: 20 | AJ4: 21 | AK4: 22 | AL4: 23 | AM4: 24 | AN4: 25 | AO4: 26 | AP4: 27 | AQ4: 28 | AR4: 29 | AS4: 30 | AT4: 31 | AU4: 32 | AV4: 33 | AW4: 34 | AX4: 35 | AY4: 36 | AZ4: 37 | BA4: 38 | BB4: 39 | BC4: 40 | BD4: 41 | BE4: 42 | BF4: 43 | BG4: 44 | BH4: 45 | BI4: 46 | BJ4: 47 | BK4: 48 | BL4: 49 | BM4: 50 | BN4: 51 | BO4: 52 | BP4: 53 | BQ4: 54 | BR4: 55 | BS4: 56 | BT4: 57 | BU4: 58 | BV4: 59 | BW4: 60 | BX4: 61 | BY4: 62 | BZ4: 63 | CA4: 64 | CB4: 65 | CC4: 66 | CD4: 67 | CE4: 68 | CF4: 69 | CG4: 70 | CH4: 71 | CI4: 72 | CJ4: 73 | CK4: 74 | CL4: 75 | CM4: 76 | CN4: 77 | CO4: 78 | CP4: 79 | CQ4: 80 | CR4: 81 | CS4: 82 | CT4: 83 | CU4: 84 | CV4: 85 | CW4: 86 | CX4: 87 | CY4: 88 | CZ4: 89 | DA4: 90 | DB4: 91 | DC4: 92 | DD4: 93 | DE4: 94 | DF4: 95 | DG4: 96 | DH4: 97 | DI4: 98 | DJ4: 99 | DK4: 100 | DL4: 101 | DM4: 102 | DN4: 103 | DO4: 104 | DP4: 105 | DQ4: 106 | DR4: 107 | DS4: 108 | DT4: 109 | DU4: 110 | DV4: 111 | DW4: 112 | DX4: 113 | DY4: 114 | DZ4: 115 | EA4: 116 | EB4: 117 | EC4: 118 | ED4: 119 | EE4: 120 | EF4: 121 | EG4: 122 | EH4: 123 | EI4: 124 | EJ4: 125 | EK4: 126 | EL4: 127 | EM4: 128 | EN4: 129 | EO4: 130 | EP4: 131 | EQ4: 132 | ER4: 133 | ES4: 134 | ET4: 135 | EU4: 136 | EV4: 137 | EW4: 138 | EX4: 139 | EY4: 140 | EZ4: 141 | FA4: 142 | FB4: 143 | FC4: 144 | FD4: 145 | FE4: 146 | FF4: 147 | FG4: 148 | FH4: 149 | FI4: 150 | FJ4: 151 | FK4: 152 | FL4: 153 | FM4: 154 | FN4: 155 | FO4: 156 | FP4: 157 | FQ4: 158 | FR4: 159 | FS4: 160 | FT4: 161 | FU4: 162 | FV4: 163 | FW4: 164 | FX4: 165 | FY4: 166 | FZ4: 167 | GA4: 168 | GB4: 169 | GC4: 170 | GD4: 171 | GE4: 172 | GF4: 173 | GG4: 174 | GH4: 175 | GI4: 176 | GJ4: 177 | GK4: 178 | GL4: 179 | GM4: 180
A5: ABCW011-1 | B5: 46062 | C5: =TODAY()-B5+1 -> 147 | D5: {=_xlfn.IFS(AND(TODAY()-B5<=30,TODAY()-B5>=0),"新品期",AND(TODAY()-B5>=31,TODAY()-B5<=120),"热销期",AND(TODAY()-B5>=121,TODAY()-B5<=180),"清货期",TODAY()-B5>180,"滞销")} -> 清货期 | E5: =L5-G5 -> 3569 | G5: =SUMIF([1]销售表!I:I,A5,[1]销售表!J:J) -> 1431 | H5: =G5/L5 -> 0.2862 | J5: =SUMIFS([1]销售表!J:J,[1]销售表!I:I,A5,[1]销售表!E:E,"可取") -> 41 | L5: 5000 | M5: =_xlfn.XLOOKUP(A5,[1]销售表!I:I,[1]销售表!J:J,0,0,-1) -> 8 | N5: {=IF(C5>180,"0",INDEX(P5:GM5,C5))} -> 27.777778 | O5: 销售计划 | P5: =$L5*80%/180 -> 22.222222 | Q5: =$L5*80%/180 -> 22.222222 | R5: =$L5*80%/180 -> 22.222222 | S5: =$L5*80%/180 -> 22.222222 | T5: =$L5*80%/180 -> 22.222222 | U5: =$L5*80%/180 -> 22.222222 | V5: =$L5*80%/180 -> 22.222222 | W5: =$L5*80%/180 -> 22.222222 | ... AS5: =$L5*80%/180 -> 22.222222 | AT5: =$L5*110%/180 -> 30.555556 | AU5: =$L5*110%/180 -> 30.555556 | AV5: =$L5*110%/180 -> 30.555556 | AW5: =$L5*110%/180 -> 30.555556 | AX5: =$L5*110%/180 -> 30.555556 | AY5: =$L5*110%/180 -> 30.555556 | AZ5: =$L5*110%/180 -> 30.555556 | BA5: =$L5*110%/180 -> 30.555556 | ... EE5: =$L5*110%/180 -> 30.555556 | EF5: =$L5*100%/180 -> 27.777778 | EG5: =$L5*100%/180 -> 27.777778 | EH5: =$L5*100%/180 -> 27.777778 | EI5: =$L5*100%/180 -> 27.777778 | EJ5: =$L5*100%/180 -> 27.777778 | EK5: =$L5*100%/180 -> 27.777778 | EL5: =$L5*100%/180 -> 27.777778 | EM5: =$L5*100%/180 -> 27.777778 | ... GM5: =$L5*100%/180 -> 27.777778
A6: ABCW011-1 | B6: 46062 | C6: =TODAY()-B6+1 -> 147 | D6: {=_xlfn.IFS(AND(TODAY()-B6<=30,TODAY()-B6>=0),"新品期",AND(TODAY()-B6>=31,TODAY()-B6<=120),"热销期",AND(TODAY()-B6>=121,TODAY()-B6<=180),"清货期",TODAY()-B6>180,"滞销")} -> 清货期 | E6: =L6-G6 -> 3569 | G6: =SUMIF([1]销售表!I:I,A6,[1]销售表!J:J) -> 1431 | H6: =G6/L6 -> 0.2862 | J6: =SUMIFS([1]销售表!J:J,[1]销售表!I:I,A6,[1]销售表!E:E,"可取") -> 41 | L6: 5000 | M6: =_xlfn.XLOOKUP(A6,[1]销售表!I:I,[1]销售表!J:J,0,0,-1) -> 8 | N6: {=IF(C6>180,"0",INDEX(P6:GM6,C6))} -> #REF! | O6: 实际销售 | P6: =SUMIFS(#REF!,#REF!,$A6,#REF!,$P$4) -> #REF! | Q6: =IF($C6>Q$4,SUMIFS(#REF!,#REF!,$A6,#REF!,Q$4),($L6-SUM($P6))*80%/(180-P$4)) -> #REF! | R6: =IF($C6>R$4,SUMIFS(#REF!,#REF!,$A6,#REF!,R$4),($L6-SUM($P6:Q6))*80%/(180-Q$4)) -> #REF! | S6: =IF($C6>S$4,SUMIFS(#REF!,#REF!,$A6,#REF!,S$4),($L6-SUM($P6:R6))*80%/(180-R$4)) -> #REF! | T6: =IF($C6>T$4,SUMIFS(#REF!,#REF!,$A6,#REF!,T$4),($L6-SUM($P6:S6))*80%/(180-S$4)) -> #REF! | U6: =IF($C6>U$4,SUMIFS(#REF!,#REF!,$A6,#REF!,U$4),($L6-SUM($P6:T6))*80%/(180-T$4)) -> #REF! | V6: =IF($C6>V$4,SUMIFS(#REF!,#REF!,$A6,#REF!,V$4),($L6-SUM($P6:U6))*80%/(180-U$4)) -> #REF! | W6: =IF($C6>W$4,SUMIFS(#REF!,#REF!,$A6,#REF!,W$4),($L6-SUM($P6:V6))*80%/(180-V$4)) -> #REF! | X6: =IF($C6>X$4,SUMIFS(#REF!,#REF!,$A6,#REF!,X$4),($L6-SUM($P6:W6))*80%/(180-W$4)) -> #REF! | Y6: =IF($C6>Y$4,SUMIFS(#REF!,#REF!,$A6,#REF!,Y$4),($L6-SUM($P6:X6))*80%/(180-X$4)) -> #REF! | ... AS6: =IF($C6>AS$4,SUMIFS(#REF!,#REF!,$A6,#REF!,AS$4),($L6-SUM($P6:AR6))*80%/(180-AR$4)) -> #REF! | AT6: =IF($C6>AT$4,SUMIFS(#REF!,#REF!,$A6,#REF!,AT$4),($L6-SUM($P6:AS6))*110%/(180-AS$4)) -> #REF! | AU6: =IF($C6>AU$4,SUMIFS(#REF!,#REF!,$A6,#REF!,AU$4),($L6-SUM($P6:AT6))*110%/(180-AT$4)) -> #REF! | AV6: =IF($C6>AV$4,SUMIFS(#REF!,#REF!,$A6,#REF!,AV$4),($L6-SUM($P6:AU6))*110%/(180-AU$4)) -> #REF! | AW6: =IF($C6>AW$4,SUMIFS(#REF!,#REF!,$A6,#REF!,AW$4),($L6-SUM($P6:AV6))*110%/(180-AV$4)) -> #REF! | AX6: =IF($C6>AX$4,SUMIFS(#REF!,#REF!,$A6,#REF!,AX$4),($L6-SUM($P6:AW6))*110%/(180-AW$4)) -> #REF! | AY6: =IF($C6>AY$4,SUMIFS(#REF!,#REF!,$A6,#REF!,AY$4),($L6-SUM($P6:AX6))*110%/(180-AX$4)) -> #REF! | AZ6: =IF($C6>AZ$4,SUMIFS(#REF!,#REF!,$A6,#REF!,AZ$4),($L6-SUM($P6:AY6))*110%/(180-AY$4)) -> #REF! | BA6: =IF($C6>BA$4,SUMIFS(#REF!,#REF!,$A6,#REF!,BA$4),($L6-SUM($P6:AZ6))*110%/(180-AZ$4)) -> #REF! | ... EE6: =IF($C6>EE$4,SUMIFS(#REF!,#REF!,$A6,#REF!,EE$4),($L6-SUM($P6:ED6))*110%/(180-ED$4)) -> #REF! | EF6: =IF($C6>EF$4,SUMIFS(#REF!,#REF!,$A6,#REF!,EF$4),($L6-SUM($P6:EE6))*100%/(180-EE$4)) -> #REF! | EG6: =IF($C6>EG$4,SUMIFS(#REF!,#REF!,$A6,#REF!,EG$4),($L6-SUM($P6:EF6))*100%/(180-EF$4)) -> #REF! | EH6: =IF($C6>EH$4,SUMIFS(#REF!,#REF!,$A6,#REF!,EH$4),($L6-SUM($P6:EG6))*100%/(180-EG$4)) -> #REF! | EI6: =IF($C6>EI$4,SUMIFS(#REF!,#REF!,$A6,#REF!,EI$4),($L6-SUM($P6:EH6))*100%/(180-EH$4)) -> #REF! | EJ6: =IF($C6>EJ$4,SUMIFS(#REF!,#REF!,$A6,#REF!,EJ$4),($L6-SUM($P6:EI6))*100%/(180-EI$4)) -> #REF! | EK6: =IF($C6>EK$4,SUMIFS(#REF!,#REF!,$A6,#REF!,EK$4),($L6-SUM($P6:EJ6))*100%/(180-EJ$4)) -> #REF! | EL6: =IF($C6>EL$4,SUMIFS(#REF!,#REF!,$A6,#REF!,EL$4),($L6-SUM($P6:EK6))*100%/(180-EK$4)) -> #REF! | EM6: =IF($C6>EM$4,SUMIFS(#REF!,#REF!,$A6,#REF!,EM$4),($L6-SUM($P6:EL6))*100%/(180-EL$4)) -> #REF! | ... GM6: =IF($C6>GM$4,SUMIFS(#REF!,#REF!,$A6,#REF!,GM$4),($L6-SUM($P6:GL6))*100%/(180-GL$4)) -> #REF!
A7: ABCW011-1 | B7: 46062 | C7: =TODAY()-B7+1 -> 147 | D7: {=_xlfn.IFS(AND(TODAY()-B7<=30,TODAY()-B7>=0),"新品期",AND(TODAY()-B7>=31,TODAY()-B7<=120),"热销期",AND(TODAY()-B7>=121,TODAY()-B7<=180),"清货期",TODAY()-B7>180,"滞销")} -> 清货期 | E7: =L7-G7 -> 3569 | G7: =SUMIF([1]销售表!I:I,A7,[1]销售表!J:J) -> 1431 | H7: =G7/L7 -> 0.2862 | J7: =SUMIFS([1]销售表!J:J,[1]销售表!I:I,A7,[1]销售表!E:E,"可取") -> 41 | L7: 5000 | M7: =_xlfn.XLOOKUP(A7,[1]销售表!I:I,[1]销售表!J:J,0,0,-1) -> 8 | N7: {=IF(C7>180,"0",INDEX(P7:GM7,C7))} -> #REF! | O7: 销售计划（有销售后） | P7: =$L7*80%/180 -> 22.222222 | Q7: {=_xlfn.IFS(Q$4<$C7,($L7-SUMIFS(#REF!,#REF!,$A7,#REF!,"<="&P$4))*80%/(180-P$4),Q$4>=$C7,($L7-SUM(#REF!))*80%/(180-P$4))} -> #REF! | R7: {=_xlfn.IFS(R$4<$C7,($L7-SUMIFS(#REF!,#REF!,$A7,#REF!,"<="&Q$4))*80%/(180-Q$4),R$4>=$C7,($L7-SUM(#REF!))*80%/(180-Q$4))} -> #REF! | S7: {=_xlfn.IFS(S$4<$C7,($L7-SUMIFS(#REF!,#REF!,$A7,#REF!,"<="&R$4))*80%/(180-R$4),S$4>=$C7,($L7-SUM(#REF!))*80%/(180-R$4))} -> #REF! | T7: {=_xlfn.IFS(T$4<$C7,($L7-SUMIFS(#REF!,#REF!,$A7,#REF!,"<="&S$4))*80%/(180-S$4),T$4>=$C7,($L7-SUM(#REF!))*80%/(180-S$4))} -> #REF! | U7: {=_xlfn.IFS(U$4<$C7,($L7-SUMIFS(#REF!,#REF!,$A7,#REF!,"<="&T$4))*80%/(180-T$4),U$4>=$C7,($L7-SUM(#REF!))*80%/(180-T$4))} -> #REF! | V7: {=_xlfn.IFS(V$4<$C7,($L7-SUMIFS(#REF!,#REF!,$A7,#REF!,"<="&U$4))*80%/(180-U$4),V$4>=$C7,($L7-SUM(#REF!))*80%/(180-U$4))} -> #REF! | W7: {=_xlfn.IFS(W$4<$C7,($L7-SUMIFS(#REF!,#REF!,$A7,#REF!,"<="&V$4))*80%/(180-V$4),W$4>=$C7,($L7-SUM(#REF!))*80%/(180-V$4))} -> #REF! | X7: {=_xlfn.IFS(X$4<$C7,($L7-SUMIFS(#REF!,#REF!,$A7,#REF!,"<="&W$4))*80%/(180-W$4),X$4>=$C7,($L7-SUM(#REF!))*80%/(180-W$4))} -> #REF! | ... AS7: {=_xlfn.IFS(AS$4<$C7,($L7-SUMIFS(#REF!,#REF!,$A7,#REF!,"<="&AR$4))*80%/(180-AR$4),AS$4>=$C7,($L7-SUM(#REF!))*80%/(180-AR$4))} -> #REF! | AT7: {=_xlfn.IFS(AT$4<$C7,($L7-SUMIFS(#REF!,#REF!,$A7,#REF!,"<="&AS$4))*110%/(180-AS$4),AT$4>=$C7,($L7-SUM(#REF!))*110%/(180-AS$4))} -> #REF! | AU7: {=_xlfn.IFS(AU$4<$C7,($L7-SUMIFS(#REF!,#REF!,$A7,#REF!,"<="&AT$4))*110%/(180-AT$4),AU$4>=$C7,($L7-SUM(#REF!))*110%/(180-AT$4))} -> #REF! | AV7: {=_xlfn.IFS(AV$4<$C7,($L7-SUMIFS(#REF!,#REF!,$A7,#REF!,"<="&AU$4))*110%/(180-AU$4),AV$4>=$C7,($L7-SUM(#REF!))*110%/(180-AU$4))} -> #REF! | AW7: {=_xlfn.IFS(AW$4<$C7,($L7-SUMIFS(#REF!,#REF!,$A7,#REF!,"<="&AV$4))*110%/(180-AV$4),AW$4>=$C7,($L7-SUM(#REF!))*110%/(180-AV$4))} -> #REF! | AX7: {=_xlfn.IFS(AX$4<$C7,($L7-SUMIFS(#REF!,#REF!,$A7,#REF!,"<="&AW$4))*110%/(180-AW$4),AX$4>=$C7,($L7-SUM(#REF!))*110%/(180-AW$4))} -> #REF! | AY7: {=_xlfn.IFS(AY$4<$C7,($L7-SUMIFS(#REF!,#REF!,$A7,#REF!,"<="&AX$4))*110%/(180-AX$4),AY$4>=$C7,($L7-SUM(#REF!))*110%/(180-AX$4))} -> #REF! | AZ7: {=_xlfn.IFS(AZ$4<$C7,($L7-SUMIFS(#REF!,#REF!,$A7,#REF!,"<="&AY$4))*110%/(180-AY$4),AZ$4>=$C7,($L7-SUM(#REF!))*110%/(180-AY$4))} -> #REF! | BA7: {=_xlfn.IFS(BA$4<$C7,($L7-SUMIFS(#REF!,#REF!,$A7,#REF!,"<="&AZ$4))*110%/(180-AZ$4),BA$4>=$C7,($L7-SUM(#REF!))*110%/(180-AZ$4))} -> #REF! | ... EE7: {=_xlfn.IFS(EE$4<$C7,($L7-SUMIFS(#REF!,#REF!,$A7,#REF!,"<="&ED$4))*110%/(180-ED$4),EE$4>=$C7,($L7-SUM(#REF!))*110%/(180-ED$4))} -> #REF! | EF7: {=_xlfn.IFS(EF$4<$C7,($L7-SUMIFS(#REF!,#REF!,$A7,#REF!,"<="&EE$4))*100%/(180-EE$4),EF$4>=$C7,($L7-SUM(#REF!))*100%/(180-EE$4))} -> #REF! | EG7: {=_xlfn.IFS(EG$4<$C7,($L7-SUMIFS(#REF!,#REF!,$A7,#REF!,"<="&EF$4))*100%/(180-EF$4),EG$4>=$C7,($L7-SUM(#REF!))*100%/(180-EF$4))} -> #REF! | EH7: {=_xlfn.IFS(EH$4<$C7,($L7-SUMIFS(#REF!,#REF!,$A7,#REF!,"<="&EG$4))*100%/(180-EG$4),EH$4>=$C7,($L7-SUM(#REF!))*100%/(180-EG$4))} -> #REF! | EI7: {=_xlfn.IFS(EI$4<$C7,($L7-SUMIFS(#REF!,#REF!,$A7,#REF!,"<="&EH$4))*100%/(180-EH$4),EI$4>=$C7,($L7-SUM(#REF!))*100%/(180-EH$4))} -> #REF! | EJ7: {=_xlfn.IFS(EJ$4<$C7,($L7-SUMIFS(#REF!,#REF!,$A7,#REF!,"<="&EI$4))*100%/(180-EI$4),EJ$4>=$C7,($L7-SUM(#REF!))*100%/(180-EI$4))} -> #REF! | EK7: {=_xlfn.IFS(EK$4<$C7,($L7-SUMIFS(#REF!,#REF!,$A7,#REF!,"<="&EJ$4))*100%/(180-EJ$4),EK$4>=$C7,($L7-SUM(#REF!))*100%/(180-EJ$4))} -> #REF! | EL7: {=_xlfn.IFS(EL$4<$C7,($L7-SUMIFS(#REF!,#REF!,$A7,#REF!,"<="&EK$4))*100%/(180-EK$4),EL$4>=$C7,($L7-SUM(#REF!))*100%/(180-EK$4))} -> #REF! | EM7: {=_xlfn.IFS(EM$4<$C7,($L7-SUMIFS(#REF!,#REF!,$A7,#REF!,"<="&EL$4))*100%/(180-EL$4),EM$4>=$C7,($L7-SUM(#REF!))*100%/(180-EL$4))} -> #REF! | ... GM7: {=_xlfn.IFS(GM$4<$C7,($L7-SUMIFS(#REF!,#REF!,$A7,#REF!,"<="&GL$4))*100%/(180-GL$4),GM$4>=$C7,($L7-SUM(#REF!))*100%/(180-GL$4))} -> #REF!
A8: ABAV085-3 | B8: 46134 | C8: =TODAY()-B8+1 -> 75 | D8: {=_xlfn.IFS(AND(TODAY()-B8<=30,TODAY()-B8>=0),"新品期",AND(TODAY()-B8>=31,TODAY()-B8<=120),"热销期",AND(TODAY()-B8>=121,TODAY()-B8<=180),"清货期",TODAY()-B8>180,"滞销")} -> 热销期 | E8: =L8-G8 -> 2366 | G8: =SUMIF([1]销售表!I:I,A8,[1]销售表!J:J) -> 634 | H8: =G8/L8 -> 0.21133333 | J8: =SUMIFS([1]销售表!J:J,[1]销售表!I:I,A8,[1]销售表!E:E,"可取") -> 82 | L8: 3000 | O8: 销售计划 | P8: =$L8*80%/180 -> 13.333333 | Q8: =$L8*80%/180 -> 13.333333 | R8: =$L8*80%/180 -> 13.333333 | S8: =$L8*80%/180 -> 13.333333 | T8: =$L8*80%/180 -> 13.333333 | U8: =$L8*80%/180 -> 13.333333 | V8: =$L8*80%/180 -> 13.333333 | W8: =$L8*80%/180 -> 13.333333 | ... AS8: =$L8*80%/180 -> 13.333333 | AT8: =$L8*110%/180 -> 18.333333 | AU8: =$L8*110%/180 -> 18.333333 | AV8: =$L8*110%/180 -> 18.333333 | AW8: =$L8*110%/180 -> 18.333333 | AX8: =$L8*110%/180 -> 18.333333 | AY8: =$L8*110%/180 -> 18.333333 | AZ8: =$L8*110%/180 -> 18.333333 | BA8: =$L8*110%/180 -> 18.333333 | ... EE8: =$L8*110%/180 -> 18.333333 | EF8: =$L8*100%/180 -> 16.666667 | EG8: =$L8*100%/180 -> 16.666667 | EH8: =$L8*100%/180 -> 16.666667 | EI8: =$L8*100%/180 -> 16.666667 | EJ8: =$L8*100%/180 -> 16.666667 | EK8: =$L8*100%/180 -> 16.666667 | EL8: =$L8*100%/180 -> 16.666667 | EM8: =$L8*100%/180 -> 16.666667 | ... GM8: =$L8*100%/180 -> 16.666667
A9: ABAV085-3 | B9: 46134 | C9: =TODAY()-B9+1 -> 75 | D9: {=_xlfn.IFS(AND(TODAY()-B9<=30,TODAY()-B9>=0),"新品期",AND(TODAY()-B9>=31,TODAY()-B9<=120),"热销期",AND(TODAY()-B9>=121,TODAY()-B9<=180),"清货期",TODAY()-B9>180,"滞销")} -> 热销期 | E9: =L9-G9 -> 2366 | G9: =SUMIF([1]销售表!I:I,A9,[1]销售表!J:J) -> 634 | H9: =G9/L9 -> 0.21133333 | J9: =SUMIFS([1]销售表!J:J,[1]销售表!I:I,A9,[1]销售表!E:E,"可取") -> 61 | L9: 3000 | M9: =_xlfn.XLOOKUP(A9,[1]销售表!I:I,[1]销售表!J:J,0,0,-1) -> 15 | N9: {=IF(C9>180,"0",INDEX(P9:GM9,C9))} -> #REF! | O9: 实际销售 | P9: =SUMIFS(#REF!,#REF!,$A9,#REF!,$P$4) -> #REF! | Q9: =IF($C9>Q$4,SUMIFS(#REF!,#REF!,$A9,#REF!,Q$4),($L9-SUM($P9))*80%/(180-P$4)) -> #REF! | R9: =IF($C9>R$4,SUMIFS(#REF!,#REF!,$A9,#REF!,R$4),($L9-SUM($P9:Q9))*80%/(180-Q$4)) -> #REF! | S9: =IF($C9>S$4,SUMIFS(#REF!,#REF!,$A9,#REF!,S$4),($L9-SUM($P9:R9))*80%/(180-R$4)) -> #REF! | T9: =IF($C9>T$4,SUMIFS(#REF!,#REF!,$A9,#REF!,T$4),($L9-SUM($P9:S9))*80%/(180-S$4)) -> #REF! | U9: =IF($C9>U$4,SUMIFS(#REF!,#REF!,$A9,#REF!,U$4),($L9-SUM($P9:T9))*80%/(180-T$4)) -> #REF! | V9: =IF($C9>V$4,SUMIFS(#REF!,#REF!,$A9,#REF!,V$4),($L9-SUM($P9:U9))*80%/(180-U$4)) -> #REF! | W9: =IF($C9>W$4,SUMIFS(#REF!,#REF!,$A9,#REF!,W$4),($L9-SUM($P9:V9))*80%/(180-V$4)) -> #REF! | X9: =IF($C9>X$4,SUMIFS(#REF!,#REF!,$A9,#REF!,X$4),($L9-SUM($P9:W9))*80%/(180-W$4)) -> #REF! | Y9: =IF($C9>Y$4,SUMIFS(#REF!,#REF!,$A9,#REF!,Y$4),($L9-SUM($P9:X9))*80%/(180-X$4)) -> #REF! | ... AS9: =IF($C9>AS$4,SUMIFS(#REF!,#REF!,$A9,#REF!,AS$4),($L9-SUM($P9:AR9))*80%/(180-AR$4)) -> #REF! | AT9: =IF($C9>AT$4,SUMIFS(#REF!,#REF!,$A9,#REF!,AT$4),($L9-SUM($P9:AS9))*110%/(180-AS$4)) -> #REF! | AU9: =IF($C9>AU$4,SUMIFS(#REF!,#REF!,$A9,#REF!,AU$4),($L9-SUM($P9:AT9))*110%/(180-AT$4)) -> #REF! | AV9: =IF($C9>AV$4,SUMIFS(#REF!,#REF!,$A9,#REF!,AV$4),($L9-SUM($P9:AU9))*110%/(180-AU$4)) -> #REF! | AW9: =IF($C9>AW$4,SUMIFS(#REF!,#REF!,$A9,#REF!,AW$4),($L9-SUM($P9:AV9))*110%/(180-AV$4)) -> #REF! | AX9: =IF($C9>AX$4,SUMIFS(#REF!,#REF!,$A9,#REF!,AX$4),($L9-SUM($P9:AW9))*110%/(180-AW$4)) -> #REF! | AY9: =IF($C9>AY$4,SUMIFS(#REF!,#REF!,$A9,#REF!,AY$4),($L9-SUM($P9:AX9))*110%/(180-AX$4)) -> #REF! | AZ9: =IF($C9>AZ$4,SUMIFS(#REF!,#REF!,$A9,#REF!,AZ$4),($L9-SUM($P9:AY9))*110%/(180-AY$4)) -> #REF! | BA9: =IF($C9>BA$4,SUMIFS(#REF!,#REF!,$A9,#REF!,BA$4),($L9-SUM($P9:AZ9))*110%/(180-AZ$4)) -> #REF! | ... EE9: =IF($C9>EE$4,SUMIFS(#REF!,#REF!,$A9,#REF!,EE$4),($L9-SUM($P9:ED9))*110%/(180-ED$4)) -> #REF! | EF9: =IF($C9>EF$4,SUMIFS(#REF!,#REF!,$A9,#REF!,EF$4),($L9-SUM($P9:EE9))*100%/(180-EE$4)) -> #REF! | EG9: =IF($C9>EG$4,SUMIFS(#REF!,#REF!,$A9,#REF!,EG$4),($L9-SUM($P9:EF9))*100%/(180-EF$4)) -> #REF! | EH9: =IF($C9>EH$4,SUMIFS(#REF!,#REF!,$A9,#REF!,EH$4),($L9-SUM($P9:EG9))*100%/(180-EG$4)) -> #REF! | EI9: =IF($C9>EI$4,SUMIFS(#REF!,#REF!,$A9,#REF!,EI$4),($L9-SUM($P9:EH9))*100%/(180-EH$4)) -> #REF! | EJ9: =IF($C9>EJ$4,SUMIFS(#REF!,#REF!,$A9,#REF!,EJ$4),($L9-SUM($P9:EI9))*100%/(180-EI$4)) -> #REF! | EK9: =IF($C9>EK$4,SUMIFS(#REF!,#REF!,$A9,#REF!,EK$4),($L9-SUM($P9:EJ9))*100%/(180-EJ$4)) -> #REF! | EL9: =IF($C9>EL$4,SUMIFS(#REF!,#REF!,$A9,#REF!,EL$4),($L9-SUM($P9:EK9))*100%/(180-EK$4)) -> #REF! | EM9: =IF($C9>EM$4,SUMIFS(#REF!,#REF!,$A9,#REF!,EM$4),($L9-SUM($P9:EL9))*100%/(180-EL$4)) -> #REF! | ... GM9: =IF($C9>GM$4,SUMIFS(#REF!,#REF!,$A9,#REF!,GM$4),($L9-SUM($P9:GL9))*100%/(180-GL$4)) -> #REF!
A10: ABAV085-3 | B10: 46134 | C10: =TODAY()-B10+1 -> 75 | D10: {=_xlfn.IFS(AND(TODAY()-B10<=30,TODAY()-B10>=0),"新品期",AND(TODAY()-B10>=31,TODAY()-B10<=120),"热销期",AND(TODAY()-B10>=121,TODAY()-B10<=180),"清货期",TODAY()-B10>180,"滞销")} -> 热销期 | E10: =L10-G10 -> 2366 | G10: =SUMIF([1]销售表!I:I,A10,[1]销售表!J:J) -> 634 | H10: =G10/L10 -> 0.21133333 | J10: =SUMIFS([1]销售表!J:J,[1]销售表!I:I,A10,[1]销售表!E:E,"可取") -> 61 | L10: 3000 | O10: 销售计划（有销售后） | P10: =$L10*80%/180 -> 13.333333 | Q10: {=_xlfn.IFS(Q$4<$C10,($L10-SUMIFS(#REF!,#REF!,$A10,#REF!,"<="&P$4))*80%/(180-P$4),Q$4>=$C10,($L10-SUM(#REF!))*80%/(180-P$4))} -> #REF! | R10: {=_xlfn.IFS(R$4<$C10,($L10-SUMIFS(#REF!,#REF!,$A10,#REF!,"<="&Q$4))*80%/(180-Q$4),R$4>=$C10,($L10-SUM(#REF!))*80%/(180-Q$4))} -> #REF! | S10: {=_xlfn.IFS(S$4<$C10,($L10-SUMIFS(#REF!,#REF!,$A10,#REF!,"<="&R$4))*80%/(180-R$4),S$4>=$C10,($L10-SUM(#REF!))*80%/(180-R$4))} -> #REF! | T10: {=_xlfn.IFS(T$4<$C10,($L10-SUMIFS(#REF!,#REF!,$A10,#REF!,"<="&S$4))*80%/(180-S$4),T$4>=$C10,($L10-SUM(#REF!))*80%/(180-S$4))} -> #REF! | U10: {=_xlfn.IFS(U$4<$C10,($L10-SUMIFS(#REF!,#REF!,$A10,#REF!,"<="&T$4))*80%/(180-T$4),U$4>=$C10,($L10-SUM(#REF!))*80%/(180-T$4))} -> #REF! | V10: {=_xlfn.IFS(V$4<$C10,($L10-SUMIFS(#REF!,#REF!,$A10,#REF!,"<="&U$4))*80%/(180-U$4),V$4>=$C10,($L10-SUM(#REF!))*80%/(180-U$4))} -> #REF! | W10: {=_xlfn.IFS(W$4<$C10,($L10-SUMIFS(#REF!,#REF!,$A10,#REF!,"<="&V$4))*80%/(180-V$4),W$4>=$C10,($L10-SUM(#REF!))*80%/(180-V$4))} -> #REF! | X10: {=_xlfn.IFS(X$4<$C10,($L10-SUMIFS(#REF!,#REF!,$A10,#REF!,"<="&W$4))*80%/(180-W$4),X$4>=$C10,($L10-SUM(#REF!))*80%/(180-W$4))} -> #REF! | ... AS10: {=_xlfn.IFS(AS$4<$C10,($L10-SUMIFS(#REF!,#REF!,$A10,#REF!,"<="&AR$4))*80%/(180-AR$4),AS$4>=$C10,($L10-SUM(#REF!))*80%/(180-AR$4))} -> #REF! | AT10: {=_xlfn.IFS(AT$4<$C10,($L10-SUMIFS(#REF!,#REF!,$A10,#REF!,"<="&AS$4))*110%/(180-AS$4),AT$4>=$C10,($L10-SUM(#REF!))*110%/(180-AS$4))} -> #REF! | AU10: {=_xlfn.IFS(AU$4<$C10,($L10-SUMIFS(#REF!,#REF!,$A10,#REF!,"<="&AT$4))*110%/(180-AT$4),AU$4>=$C10,($L10-SUM(#REF!))*110%/(180-AT$4))} -> #REF! | AV10: {=_xlfn.IFS(AV$4<$C10,($L10-SUMIFS(#REF!,#REF!,$A10,#REF!,"<="&AU$4))*110%/(180-AU$4),AV$4>=$C10,($L10-SUM(#REF!))*110%/(180-AU$4))} -> #REF! | AW10: {=_xlfn.IFS(AW$4<$C10,($L10-SUMIFS(#REF!,#REF!,$A10,#REF!,"<="&AV$4))*110%/(180-AV$4),AW$4>=$C10,($L10-SUM(#REF!))*110%/(180-AV$4))} -> #REF! | AX10: {=_xlfn.IFS(AX$4<$C10,($L10-SUMIFS(#REF!,#REF!,$A10,#REF!,"<="&AW$4))*110%/(180-AW$4),AX$4>=$C10,($L10-SUM(#REF!))*110%/(180-AW$4))} -> #REF! | AY10: {=_xlfn.IFS(AY$4<$C10,($L10-SUMIFS(#REF!,#REF!,$A10,#REF!,"<="&AX$4))*110%/(180-AX$4),AY$4>=$C10,($L10-SUM(#REF!))*110%/(180-AX$4))} -> #REF! | AZ10: {=_xlfn.IFS(AZ$4<$C10,($L10-SUMIFS(#REF!,#REF!,$A10,#REF!,"<="&AY$4))*110%/(180-AY$4),AZ$4>=$C10,($L10-SUM(#REF!))*110%/(180-AY$4))} -> #REF! | BA10: {=_xlfn.IFS(BA$4<$C10,($L10-SUMIFS(#REF!,#REF!,$A10,#REF!,"<="&AZ$4))*110%/(180-AZ$4),BA$4>=$C10,($L10-SUM(#REF!))*110%/(180-AZ$4))} -> #REF! | ... EE10: {=_xlfn.IFS(EE$4<$C10,($L10-SUMIFS(#REF!,#REF!,$A10,#REF!,"<="&ED$4))*110%/(180-ED$4),EE$4>=$C10,($L10-SUM(#REF!))*110%/(180-ED$4))} -> #REF! | EF10: {=_xlfn.IFS(EF$4<$C10,($L10-SUMIFS(#REF!,#REF!,$A10,#REF!,"<="&EE$4))*100%/(180-EE$4),EF$4>=$C10,($L10-SUM(#REF!))*100%/(180-EE$4))} -> #REF! | EG10: {=_xlfn.IFS(EG$4<$C10,($L10-SUMIFS(#REF!,#REF!,$A10,#REF!,"<="&EF$4))*100%/(180-EF$4),EG$4>=$C10,($L10-SUM(#REF!))*100%/(180-EF$4))} -> #REF! | EH10: {=_xlfn.IFS(EH$4<$C10,($L10-SUMIFS(#REF!,#REF!,$A10,#REF!,"<="&EG$4))*100%/(180-EG$4),EH$4>=$C10,($L10-SUM(#REF!))*100%/(180-EG$4))} -> #REF! | EI10: {=_xlfn.IFS(EI$4<$C10,($L10-SUMIFS(#REF!,#REF!,$A10,#REF!,"<="&EH$4))*100%/(180-EH$4),EI$4>=$C10,($L10-SUM(#REF!))*100%/(180-EH$4))} -> #REF! | EJ10: {=_xlfn.IFS(EJ$4<$C10,($L10-SUMIFS(#REF!,#REF!,$A10,#REF!,"<="&EI$4))*100%/(180-EI$4),EJ$4>=$C10,($L10-SUM(#REF!))*100%/(180-EI$4))} -> #REF! | EK10: {=_xlfn.IFS(EK$4<$C10,($L10-SUMIFS(#REF!,#REF!,$A10,#REF!,"<="&EJ$4))*100%/(180-EJ$4),EK$4>=$C10,($L10-SUM(#REF!))*100%/(180-EJ$4))} -> #REF! | EL10: {=_xlfn.IFS(EL$4<$C10,($L10-SUMIFS(#REF!,#REF!,$A10,#REF!,"<="&EK$4))*100%/(180-EK$4),EL$4>=$C10,($L10-SUM(#REF!))*100%/(180-EK$4))} -> #REF! | EM10: {=_xlfn.IFS(EM$4<$C10,($L10-SUMIFS(#REF!,#REF!,$A10,#REF!,"<="&EL$4))*100%/(180-EL$4),EM$4>=$C10,($L10-SUM(#REF!))*100%/(180-EL$4))} -> #REF! | ... GM10: {=_xlfn.IFS(GM$4<$C10,($L10-SUMIFS(#REF!,#REF!,$A10,#REF!,"<="&GL$4))*100%/(180-GL$4),GM$4>=$C10,($L10-SUM(#REF!))*100%/(180-GL$4))} -> #REF!
A11: ABPV009-6 | B11: 46170 | C11: =TODAY()-B11+1 -> 39 | D11: {=_xlfn.IFS(AND(TODAY()-B11<=30,TODAY()-B11>=0),"新品期",AND(TODAY()-B11>=31,TODAY()-B11<=120),"热销期",AND(TODAY()-B11>=121,TODAY()-B11<=180),"清货期",TODAY()-B11>180,"滞销")} -> 热销期 | E11: =L11-G11 -> 780 | G11: =SUMIF([1]销售表!I:I,A11,[1]销售表!J:J) -> 220 | H11: =G11/L11 -> 0.22 | J11: =SUMIFS([1]销售表!J:J,[1]销售表!I:I,A11,[1]销售表!E:E,"可取") -> 49 | L11: 1000 | M11: =_xlfn.XLOOKUP(A11,[1]销售表!I:I,[1]销售表!J:J,0,0,-1) -> 6 | N11: {=IF(C11>180,"0",INDEX(P11:GM11,C11))} -> 6.1111111 | O11: 销售计划 | P11: =$L11*80%/180 -> 4.4444444 | Q11: =$L11*80%/180 -> 4.4444444 | R11: =$L11*80%/180 -> 4.4444444 | S11: =$L11*80%/180 -> 4.4444444 | T11: =$L11*80%/180 -> 4.4444444 | U11: =$L11*80%/180 -> 4.4444444 | V11: =$L11*80%/180 -> 4.4444444 | W11: =$L11*80%/180 -> 4.4444444 | ... AS11: =$L11*80%/180 -> 4.4444444 | AT11: =$L11*110%/180 -> 6.1111111 | AU11: =$L11*110%/180 -> 6.1111111 | AV11: =$L11*110%/180 -> 6.1111111 | AW11: =$L11*110%/180 -> 6.1111111 | AX11: =$L11*110%/180 -> 6.1111111 | AY11: =$L11*110%/180 -> 6.1111111 | AZ11: =$L11*110%/180 -> 6.1111111 | BA11: =$L11*110%/180 -> 6.1111111 | ... EE11: =$L11*110%/180 -> 6.1111111 | EF11: =$L11*100%/180 -> 5.5555556 | EG11: =$L11*100%/180 -> 5.5555556 | EH11: =$L11*100%/180 -> 5.5555556 | EI11: =$L11*100%/180 -> 5.5555556 | EJ11: =$L11*100%/180 -> 5.5555556 | EK11: =$L11*100%/180 -> 5.5555556 | EL11: =$L11*100%/180 -> 5.5555556 | EM11: =$L11*100%/180 -> 5.5555556 | ... GM11: =$L11*100%/180 -> 5.5555556
A12: ABPV009-6 | B12: 46170 | C12: =TODAY()-B12+1 -> 39 | D12: {=_xlfn.IFS(AND(TODAY()-B12<=30,TODAY()-B12>=0),"新品期",AND(TODAY()-B12>=31,TODAY()-B12<=120),"热销期",AND(TODAY()-B12>=121,TODAY()-B12<=180),"清货期",TODAY()-B12>180,"滞销")} -> 热销期 | E12: =L12-G12 -> 780 | G12: =SUMIF([1]销售表!I:I,A12,[1]销售表!J:J) -> 220 | H12: =G12/L12 -> 0.22 | J12: =SUMIFS([1]销售表!J:J,[1]销售表!I:I,A12,[1]销售表!E:E,"可取") -> 49 | L12: 1000 | M12: =_xlfn.XLOOKUP(A12,[1]销售表!I:I,[1]销售表!J:J,0,0,-1) -> 6 | N12: {=IF(C12>180,"0",INDEX(P12:GM12,C12))} -> #REF! | O12: 实际销售 | P12: =SUMIFS(#REF!,#REF!,$A12,#REF!,$P$4) -> #REF! | Q12: =IF($C12>Q$4,SUMIFS(#REF!,#REF!,$A12,#REF!,Q$4),($L12-SUM($P12))*80%/(180-P$4)) -> #REF! | R12: =IF($C12>R$4,SUMIFS(#REF!,#REF!,$A12,#REF!,R$4),($L12-SUM($P12:Q12))*80%/(180-Q$4)) -> #REF! | S12: =IF($C12>S$4,SUMIFS(#REF!,#REF!,$A12,#REF!,S$4),($L12-SUM($P12:R12))*80%/(180-R$4)) -> #REF! | T12: =IF($C12>T$4,SUMIFS(#REF!,#REF!,$A12,#REF!,T$4),($L12-SUM($P12:S12))*80%/(180-S$4)) -> #REF! | U12: =IF($C12>U$4,SUMIFS(#REF!,#REF!,$A12,#REF!,U$4),($L12-SUM($P12:T12))*80%/(180-T$4)) -> #REF! | V12: =IF($C12>V$4,SUMIFS(#REF!,#REF!,$A12,#REF!,V$4),($L12-SUM($P12:U12))*80%/(180-U$4)) -> #REF! | W12: =IF($C12>W$4,SUMIFS(#REF!,#REF!,$A12,#REF!,W$4),($L12-SUM($P12:V12))*80%/(180-V$4)) -> #REF! | X12: =IF($C12>X$4,SUMIFS(#REF!,#REF!,$A12,#REF!,X$4),($L12-SUM($P12:W12))*80%/(180-W$4)) -> #REF! | Y12: =IF($C12>Y$4,SUMIFS(#REF!,#REF!,$A12,#REF!,Y$4),($L12-SUM($P12:X12))*80%/(180-X$4)) -> #REF! | ... AS12: =IF($C12>AS$4,SUMIFS(#REF!,#REF!,$A12,#REF!,AS$4),($L12-SUM($P12:AR12))*80%/(180-AR$4)) -> #REF! | AT12: =IF($C12>AT$4,SUMIFS(#REF!,#REF!,$A12,#REF!,AT$4),($L12-SUM($P12:AS12))*110%/(180-AS$4)) -> #REF! | AU12: =IF($C12>AU$4,SUMIFS(#REF!,#REF!,$A12,#REF!,AU$4),($L12-SUM($P12:AT12))*110%/(180-AT$4)) -> #REF! | AV12: =IF($C12>AV$4,SUMIFS(#REF!,#REF!,$A12,#REF!,AV$4),($L12-SUM($P12:AU12))*110%/(180-AU$4)) -> #REF! | AW12: =IF($C12>AW$4,SUMIFS(#REF!,#REF!,$A12,#REF!,AW$4),($L12-SUM($P12:AV12))*110%/(180-AV$4)) -> #REF! | AX12: =IF($C12>AX$4,SUMIFS(#REF!,#REF!,$A12,#REF!,AX$4),($L12-SUM($P12:AW12))*110%/(180-AW$4)) -> #REF! | AY12: =IF($C12>AY$4,SUMIFS(#REF!,#REF!,$A12,#REF!,AY$4),($L12-SUM($P12:AX12))*110%/(180-AX$4)) -> #REF! | AZ12: =IF($C12>AZ$4,SUMIFS(#REF!,#REF!,$A12,#REF!,AZ$4),($L12-SUM($P12:AY12))*110%/(180-AY$4)) -> #REF! | BA12: =IF($C12>BA$4,SUMIFS(#REF!,#REF!,$A12,#REF!,BA$4),($L12-SUM($P12:AZ12))*110%/(180-AZ$4)) -> #REF! | ... EE12: =IF($C12>EE$4,SUMIFS(#REF!,#REF!,$A12,#REF!,EE$4),($L12-SUM($P12:ED12))*110%/(180-ED$4)) -> #REF! | EF12: =IF($C12>EF$4,SUMIFS(#REF!,#REF!,$A12,#REF!,EF$4),($L12-SUM($P12:EE12))*100%/(180-EE$4)) -> #REF! | EG12: =IF($C12>EG$4,SUMIFS(#REF!,#REF!,$A12,#REF!,EG$4),($L12-SUM($P12:EF12))*100%/(180-EF$4)) -> #REF! | EH12: =IF($C12>EH$4,SUMIFS(#REF!,#REF!,$A12,#REF!,EH$4),($L12-SUM($P12:EG12))*100%/(180-EG$4)) -> #REF! | EI12: =IF($C12>EI$4,SUMIFS(#REF!,#REF!,$A12,#REF!,EI$4),($L12-SUM($P12:EH12))*100%/(180-EH$4)) -> #REF! | EJ12: =IF($C12>EJ$4,SUMIFS(#REF!,#REF!,$A12,#REF!,EJ$4),($L12-SUM($P12:EI12))*100%/(180-EI$4)) -> #REF! | EK12: =IF($C12>EK$4,SUMIFS(#REF!,#REF!,$A12,#REF!,EK$4),($L12-SUM($P12:EJ12))*100%/(180-EJ$4)) -> #REF! | EL12: =IF($C12>EL$4,SUMIFS(#REF!,#REF!,$A12,#REF!,EL$4),($L12-SUM($P12:EK12))*100%/(180-EK$4)) -> #REF! | EM12: =IF($C12>EM$4,SUMIFS(#REF!,#REF!,$A12,#REF!,EM$4),($L12-SUM($P12:EL12))*100%/(180-EL$4)) -> #REF! | ... GM12: =IF($C12>GM$4,SUMIFS(#REF!,#REF!,$A12,#REF!,GM$4),($L12-SUM($P12:GL12))*100%/(180-GL$4)) -> #REF!
A13: ABPV009-6 | B13: 46170 | C13: =TODAY()-B13+1 -> 39 | D13: {=_xlfn.IFS(AND(TODAY()-B13<=30,TODAY()-B13>=0),"新品期",AND(TODAY()-B13>=31,TODAY()-B13<=120),"热销期",AND(TODAY()-B13>=121,TODAY()-B13<=180),"清货期",TODAY()-B13>180,"滞销")} -> 热销期 | E13: =L13-G13 -> 780 | G13: =SUMIF([1]销售表!I:I,A13,[1]销售表!J:J) -> 220 | H13: =G13/L13 -> 0.22 | J13: =SUMIFS([1]销售表!J:J,[1]销售表!I:I,A13,[1]销售表!E:E,"可取") -> 49 | L13: 1000 | M13: =_xlfn.XLOOKUP(A13,[1]销售表!I:I,[1]销售表!J:J,0,0,-1) -> 6 | N13: {=IF(C13>180,"0",INDEX(P13:GM13,C13))} -> #REF! | O13: 销售计划（有销售后） | P13: =$L13*80%/180 -> 4.4444444 | Q13: {=_xlfn.IFS(Q$4<$C13,($L13-SUMIFS(#REF!,#REF!,$A13,#REF!,"<="&P$4))*80%/(180-P$4),Q$4>=$C13,($L13-SUM(#REF!))*80%/(180-P$4))} -> #REF! | R13: {=_xlfn.IFS(R$4<$C13,($L13-SUMIFS(#REF!,#REF!,$A13,#REF!,"<="&Q$4))*80%/(180-Q$4),R$4>=$C13,($L13-SUM(#REF!))*80%/(180-Q$4))} -> #REF! | S13: {=_xlfn.IFS(S$4<$C13,($L13-SUMIFS(#REF!,#REF!,$A13,#REF!,"<="&R$4))*80%/(180-R$4),S$4>=$C13,($L13-SUM(#REF!))*80%/(180-R$4))} -> #REF! | T13: {=_xlfn.IFS(T$4<$C13,($L13-SUMIFS(#REF!,#REF!,$A13,#REF!,"<="&S$4))*80%/(180-S$4),T$4>=$C13,($L13-SUM(#REF!))*80%/(180-S$4))} -> #REF! | U13: {=_xlfn.IFS(U$4<$C13,($L13-SUMIFS(#REF!,#REF!,$A13,#REF!,"<="&T$4))*80%/(180-T$4),U$4>=$C13,($L13-SUM(#REF!))*80%/(180-T$4))} -> #REF! | V13: {=_xlfn.IFS(V$4<$C13,($L13-SUMIFS(#REF!,#REF!,$A13,#REF!,"<="&U$4))*80%/(180-U$4),V$4>=$C13,($L13-SUM(#REF!))*80%/(180-U$4))} -> #REF! | W13: {=_xlfn.IFS(W$4<$C13,($L13-SUMIFS(#REF!,#REF!,$A13,#REF!,"<="&V$4))*80%/(180-V$4),W$4>=$C13,($L13-SUM(#REF!))*80%/(180-V$4))} -> #REF! | X13: {=_xlfn.IFS(X$4<$C13,($L13-SUMIFS(#REF!,#REF!,$A13,#REF!,"<="&W$4))*80%/(180-W$4),X$4>=$C13,($L13-SUM(#REF!))*80%/(180-W$4))} -> #REF! | ... AS13: {=_xlfn.IFS(AS$4<$C13,($L13-SUMIFS(#REF!,#REF!,$A13,#REF!,"<="&AR$4))*80%/(180-AR$4),AS$4>=$C13,($L13-SUM(#REF!))*80%/(180-AR$4))} -> #REF! | AT13: {=_xlfn.IFS(AT$4<$C13,($L13-SUMIFS(#REF!,#REF!,$A13,#REF!,"<="&AS$4))*110%/(180-AS$4),AT$4>=$C13,($L13-SUM(#REF!))*110%/(180-AS$4))} -> #REF! | AU13: {=_xlfn.IFS(AU$4<$C13,($L13-SUMIFS(#REF!,#REF!,$A13,#REF!,"<="&AT$4))*110%/(180-AT$4),AU$4>=$C13,($L13-SUM(#REF!))*110%/(180-AT$4))} -> #REF! | AV13: {=_xlfn.IFS(AV$4<$C13,($L13-SUMIFS(#REF!,#REF!,$A13,#REF!,"<="&AU$4))*110%/(180-AU$4),AV$4>=$C13,($L13-SUM(#REF!))*110%/(180-AU$4))} -> #REF! | AW13: {=_xlfn.IFS(AW$4<$C13,($L13-SUMIFS(#REF!,#REF!,$A13,#REF!,"<="&AV$4))*110%/(180-AV$4),AW$4>=$C13,($L13-SUM(#REF!))*110%/(180-AV$4))} -> #REF! | AX13: {=_xlfn.IFS(AX$4<$C13,($L13-SUMIFS(#REF!,#REF!,$A13,#REF!,"<="&AW$4))*110%/(180-AW$4),AX$4>=$C13,($L13-SUM(#REF!))*110%/(180-AW$4))} -> #REF! | AY13: {=_xlfn.IFS(AY$4<$C13,($L13-SUMIFS(#REF!,#REF!,$A13,#REF!,"<="&AX$4))*110%/(180-AX$4),AY$4>=$C13,($L13-SUM(#REF!))*110%/(180-AX$4))} -> #REF! | AZ13: {=_xlfn.IFS(AZ$4<$C13,($L13-SUMIFS(#REF!,#REF!,$A13,#REF!,"<="&AY$4))*110%/(180-AY$4),AZ$4>=$C13,($L13-SUM(#REF!))*110%/(180-AY$4))} -> #REF! | BA13: {=_xlfn.IFS(BA$4<$C13,($L13-SUMIFS(#REF!,#REF!,$A13,#REF!,"<="&AZ$4))*110%/(180-AZ$4),BA$4>=$C13,($L13-SUM(#REF!))*110%/(180-AZ$4))} -> #REF! | ... EE13: {=_xlfn.IFS(EE$4<$C13,($L13-SUMIFS(#REF!,#REF!,$A13,#REF!,"<="&ED$4))*110%/(180-ED$4),EE$4>=$C13,($L13-SUM(#REF!))*110%/(180-ED$4))} -> #REF! | EF13: {=_xlfn.IFS(EF$4<$C13,($L13-SUMIFS(#REF!,#REF!,$A13,#REF!,"<="&EE$4))*100%/(180-EE$4),EF$4>=$C13,($L13-SUM(#REF!))*100%/(180-EE$4))} -> #REF! | EG13: {=_xlfn.IFS(EG$4<$C13,($L13-SUMIFS(#REF!,#REF!,$A13,#REF!,"<="&EF$4))*100%/(180-EF$4),EG$4>=$C13,($L13-SUM(#REF!))*100%/(180-EF$4))} -> #REF! | EH13: {=_xlfn.IFS(EH$4<$C13,($L13-SUMIFS(#REF!,#REF!,$A13,#REF!,"<="&EG$4))*100%/(180-EG$4),EH$4>=$C13,($L13-SUM(#REF!))*100%/(180-EG$4))} -> #REF! | EI13: {=_xlfn.IFS(EI$4<$C13,($L13-SUMIFS(#REF!,#REF!,$A13,#REF!,"<="&EH$4))*100%/(180-EH$4),EI$4>=$C13,($L13-SUM(#REF!))*100%/(180-EH$4))} -> #REF! | EJ13: {=_xlfn.IFS(EJ$4<$C13,($L13-SUMIFS(#REF!,#REF!,$A13,#REF!,"<="&EI$4))*100%/(180-EI$4),EJ$4>=$C13,($L13-SUM(#REF!))*100%/(180-EI$4))} -> #REF! | EK13: {=_xlfn.IFS(EK$4<$C13,($L13-SUMIFS(#REF!,#REF!,$A13,#REF!,"<="&EJ$4))*100%/(180-EJ$4),EK$4>=$C13,($L13-SUM(#REF!))*100%/(180-EJ$4))} -> #REF! | EL13: {=_xlfn.IFS(EL$4<$C13,($L13-SUMIFS(#REF!,#REF!,$A13,#REF!,"<="&EK$4))*100%/(180-EK$4),EL$4>=$C13,($L13-SUM(#REF!))*100%/(180-EK$4))} -> #REF! | EM13: {=_xlfn.IFS(EM$4<$C13,($L13-SUMIFS(#REF!,#REF!,$A13,#REF!,"<="&EL$4))*100%/(180-EL$4),EM$4>=$C13,($L13-SUM(#REF!))*100%/(180-EL$4))} -> #REF! | ... GM13: {=_xlfn.IFS(GM$4<$C13,($L13-SUMIFS(#REF!,#REF!,$A13,#REF!,"<="&GL$4))*100%/(180-GL$4),GM$4>=$C13,($L13-SUM(#REF!))*100%/(180-GL$4))} -> #REF!
A14: ABAV045-2 | B14: 45971 | C14: =TODAY()-B14+1 -> 238 | D14: {=_xlfn.IFS(AND(TODAY()-B14<=30,TODAY()-B14>=0),"新品期",AND(TODAY()-B14>=31,TODAY()-B14<=120),"热销期",AND(TODAY()-B14>=121,TODAY()-B14<=180),"清货期",TODAY()-B14>180,"滞销")} -> 滞销 | E14: =L14-G14 -> 2000 | G14: =SUMIF([1]销售表!I:I,A14,[1]销售表!J:J) -> 0 | H14: =G14/L14 -> 0 | J14: =SUMIFS([1]销售表!J:J,[1]销售表!I:I,A14,[1]销售表!E:E,"可取") -> 0 | L14: 2000 | M14: =_xlfn.XLOOKUP(A14,[1]销售表!I:I,[1]销售表!J:J,0,0,-1) -> 0 | N14: {=IF(C14>180,"0",INDEX(P14:GM14,C14))} -> 0 | P14: =SUMIFS([1]销售表!J:J,[1]销售表!I:I,A14,[1]销售表!B:B,$P$4) -> 0 | Q14: =IF($C14>Q$4,SUMIFS([1]销售表!$J:$J,[1]销售表!$I:$I,$A14,[1]销售表!$B:$B,Q$4),($L14-SUM($P14))*80%/(180-P$4)) -> 0 | R14: =IF($C14>R$4,SUMIFS([1]销售表!$J:$J,[1]销售表!$I:$I,$A14,[1]销售表!$B:$B,R$4),($L14-SUM($P14:Q14))*80%/(180-Q$4)) -> 0 | S14: =IF($C14>S$4,SUMIFS([1]销售表!$J:$J,[1]销售表!$I:$I,$A14,[1]销售表!$B:$B,S$4),($L14-SUM($P14:R14))*80%/(180-R$4)) -> 0 | T14: =IF($C14>T$4,SUMIFS([1]销售表!$J:$J,[1]销售表!$I:$I,$A14,[1]销售表!$B:$B,T$4),($L14-SUM($P14:S14))*80%/(180-S$4)) -> 0 | U14: =IF($C14>U$4,SUMIFS([1]销售表!$J:$J,[1]销售表!$I:$I,$A14,[1]销售表!$B:$B,U$4),($L14-SUM($P14:T14))*80%/(180-T$4)) -> 0 | V14: =IF($C14>V$4,SUMIFS([1]销售表!$J:$J,[1]销售表!$I:$I,$A14,[1]销售表!$B:$B,V$4),($L14-SUM($P14:U14))*80%/(180-U$4)) -> 0 | W14: =IF($C14>W$4,SUMIFS([1]销售表!$J:$J,[1]销售表!$I:$I,$A14,[1]销售表!$B:$B,W$4),($L14-SUM($P14:V14))*80%/(180-V$4)) -> 0 | X14: =IF($C14>X$4,SUMIFS([1]销售表!$J:$J,[1]销售表!$I:$I,$A14,[1]销售表!$B:$B,X$4),($L14-SUM($P14:W14))*80%/(180-W$4)) -> 0 | Y14: =IF($C14>Y$4,SUMIFS([1]销售表!$J:$J,[1]销售表!$I:$I,$A14,[1]销售表!$B:$B,Y$4),($L14-SUM($P14:X14))*80%/(180-X$4)) -> 0 | ... AS14: =IF($C14>AS$4,SUMIFS([1]销售表!$J:$J,[1]销售表!$I:$I,$A14,[1]销售表!$B:$B,AS$4),($L14-SUM($P14:AR14))*80%/(180-AR$4)) -> 0 | AT14: =IF($C14>AT$4,SUMIFS([1]销售表!$J:$J,[1]销售表!$I:$I,$A14,[1]销售表!$B:$B,AT$4),($L14-SUM($P14:AS14))*110%/(180-AS$4)) -> 0 | AU14: =IF($C14>AU$4,SUMIFS([1]销售表!$J:$J,[1]销售表!$I:$I,$A14,[1]销售表!$B:$B,AU$4),($L14-SUM($P14:AT14))*110%/(180-AT$4)) -> 0 | AV14: =IF($C14>AV$4,SUMIFS([1]销售表!$J:$J,[1]销售表!$I:$I,$A14,[1]销售表!$B:$B,AV$4),($L14-SUM($P14:AU14))*110%/(180-AU$4)) -> 0 | AW14: =IF($C14>AW$4,SUMIFS([1]销售表!$J:$J,[1]销售表!$I:$I,$A14,[1]销售表!$B:$B,AW$4),($L14-SUM($P14:AV14))*110%/(180-AV$4)) -> 0 | AX14: =IF($C14>AX$4,SUMIFS([1]销售表!$J:$J,[1]销售表!$I:$I,$A14,[1]销售表!$B:$B,AX$4),($L14-SUM($P14:AW14))*110%/(180-AW$4)) -> 0 | AY14: =IF($C14>AY$4,SUMIFS([1]销售表!$J:$J,[1]销售表!$I:$I,$A14,[1]销售表!$B:$B,AY$4),($L14-SUM($P14:AX14))*110%/(180-AX$4)) -> 0 | AZ14: =IF($C14>AZ$4,SUMIFS([1]销售表!$J:$J,[1]销售表!$I:$I,$A14,[1]销售表!$B:$B,AZ$4),($L14-SUM($P14:AY14))*110%/(180-AY$4)) -> 0 | BA14: =IF($C14>BA$4,SUMIFS([1]销售表!$J:$J,[1]销售表!$I:$I,$A14,[1]销售表!$B:$B,BA$4),($L14-SUM($P14:AZ14))*110%/(180-AZ$4)) -> 0 | ... EE14: =IF($C14>EE$4,SUMIFS([1]销售表!$J:$J,[1]销售表!$I:$I,$A14,[1]销售表!$B:$B,EE$4),($L14-SUM($P14:ED14))*110%/(180-ED$4)) -> 0 | EF14: =IF($C14>EF$4,SUMIFS([1]销售表!$J:$J,[1]销售表!$I:$I,$A14,[1]销售表!$B:$B,EF$4),($L14-SUM($P14:EE14))*100%/(180-EE$4)) -> 0 | EG14: =IF($C14>EG$4,SUMIFS([1]销售表!$J:$J,[1]销售表!$I:$I,$A14,[1]销售表!$B:$B,EG$4),($L14-SUM($P14:EF14))*100%/(180-EF$4)) -> 0 | EH14: =IF($C14>EH$4,SUMIFS([1]销售表!$J:$J,[1]销售表!$I:$I,$A14,[1]销售表!$B:$B,EH$4),($L14-SUM($P14:EG14))*100%/(180-EG$4)) -> 0 | EI14: =IF($C14>EI$4,SUMIFS([1]销售表!$J:$J,[1]销售表!$I:$I,$A14,[1]销售表!$B:$B,EI$4),($L14-SUM($P14:EH14))*100%/(180-EH$4)) -> 0 | EJ14: =IF($C14>EJ$4,SUMIFS([1]销售表!$J:$J,[1]销售表!$I:$I,$A14,[1]销售表!$B:$B,EJ$4),($L14-SUM($P14:EI14))*100%/(180-EI$4)) -> 0 | EK14: =IF($C14>EK$4,SUMIFS([1]销售表!$J:$J,[1]销售表!$I:$I,$A14,[1]销售表!$B:$B,EK$4),($L14-SUM($P14:EJ14))*100%/(180-EJ$4)) -> 0 | EL14: =IF($C14>EL$4,SUMIFS([1]销售表!$J:$J,[1]销售表!$I:$I,$A14,[1]销售表!$B:$B,EL$4),($L14-SUM($P14:EK14))*100%/(180-EK$4)) -> 0 | EM14: =IF($C14>EM$4,SUMIFS([1]销售表!$J:$J,[1]销售表!$I:$I,$A14,[1]销售表!$B:$B,EM$4),($L14-SUM($P14:EL14))*100%/(180-EL$4)) -> 0 | ... GM14: =IF($C14>GM$4,SUMIFS([1]销售表!$J:$J,[1]销售表!$I:$I,$A14,[1]销售表!$B:$B,GM$4),($L14-SUM($P14:GL14))*100%/(180-GL$4)) -> 0
C15: =TODAY()-B15+1 -> 46209 | D15: {=_xlfn.IFS(AND(TODAY()-B15<=30,TODAY()-B15>=0),"新品期",AND(TODAY()-B15>=31,TODAY()-B15<=120),"热销期",AND(TODAY()-B15>=121,TODAY()-B15<=180),"清货期",TODAY()-B15>180,"滞销")} -> 滞销 | E15: =L15-G15 -> 1000 | G15: =SUMIF([1]销售表!I:I,A15,[1]销售表!J:J) -> 0 | H15: =G15/L15 -> 0 | J15: =SUMIFS([1]销售表!J:J,[1]销售表!I:I,A15,[1]销售表!E:E,"可取") -> 0 | L15: 1000 | M15: =_xlfn.XLOOKUP(A15,[1]销售表!I:I,[1]销售表!J:J,0,0,-1) -> 0 | N15: {=IF(C15>180,"0",INDEX(P15:GM15,C15))} -> 0 | P15: =SUMIFS([1]销售表!J:J,[1]销售表!I:I,A15,[1]销售表!B:B,$P$4) -> 0 | Q15: =IF($C15>Q$4,SUMIFS([1]销售表!$J:$J,[1]销售表!$I:$I,$A15,[1]销售表!$B:$B,Q$4),($L15-SUM($P15))*80%/(180-P$4)) -> 0 | R15: =IF($C15>R$4,SUMIFS([1]销售表!$J:$J,[1]销售表!$I:$I,$A15,[1]销售表!$B:$B,R$4),($L15-SUM($P15:Q15))*80%/(180-Q$4)) -> 0 | S15: =IF($C15>S$4,SUMIFS([1]销售表!$J:$J,[1]销售表!$I:$I,$A15,[1]销售表!$B:$B,S$4),($L15-SUM($P15:R15))*80%/(180-R$4)) -> 0 | T15: =IF($C15>T$4,SUMIFS([1]销售表!$J:$J,[1]销售表!$I:$I,$A15,[1]销售表!$B:$B,T$4),($L15-SUM($P15:S15))*80%/(180-S$4)) -> 0 | U15: =IF($C15>U$4,SUMIFS([1]销售表!$J:$J,[1]销售表!$I:$I,$A15,[1]销售表!$B:$B,U$4),($L15-SUM($P15:T15))*80%/(180-T$4)) -> 0 | V15: =IF($C15>V$4,SUMIFS([1]销售表!$J:$J,[1]销售表!$I:$I,$A15,[1]销售表!$B:$B,V$4),($L15-SUM($P15:U15))*80%/(180-U$4)) -> 0 | W15: =IF($C15>W$4,SUMIFS([1]销售表!$J:$J,[1]销售表!$I:$I,$A15,[1]销售表!$B:$B,W$4),($L15-SUM($P15:V15))*80%/(180-V$4)) -> 0 | X15: =IF($C15>X$4,SUMIFS([1]销售表!$J:$J,[1]销售表!$I:$I,$A15,[1]销售表!$B:$B,X$4),($L15-SUM($P15:W15))*80%/(180-W$4)) -> 0 | Y15: =IF($C15>Y$4,SUMIFS([1]销售表!$J:$J,[1]销售表!$I:$I,$A15,[1]销售表!$B:$B,Y$4),($L15-SUM($P15:X15))*80%/(180-X$4)) -> 0 | ... AS15: =IF($C15>AS$4,SUMIFS([1]销售表!$J:$J,[1]销售表!$I:$I,$A15,[1]销售表!$B:$B,AS$4),($L15-SUM($P15:AR15))*80%/(180-AR$4)) -> 0 | AT15: =IF($C15>AT$4,SUMIFS([1]销售表!$J:$J,[1]销售表!$I:$I,$A15,[1]销售表!$B:$B,AT$4),($L15-SUM($P15:AS15))*110%/(180-AS$4)) -> 0 | AU15: =IF($C15>AU$4,SUMIFS([1]销售表!$J:$J,[1]销售表!$I:$I,$A15,[1]销售表!$B:$B,AU$4),($L15-SUM($P15:AT15))*110%/(180-AT$4)) -> 0 | AV15: =IF($C15>AV$4,SUMIFS([1]销售表!$J:$J,[1]销售表!$I:$I,$A15,[1]销售表!$B:$B,AV$4),($L15-SUM($P15:AU15))*110%/(180-AU$4)) -> 0 | AW15: =IF($C15>AW$4,SUMIFS([1]销售表!$J:$J,[1]销售表!$I:$I,$A15,[1]销售表!$B:$B,AW$4),($L15-SUM($P15:AV15))*110%/(180-AV$4)) -> 0 | AX15: =IF($C15>AX$4,SUMIFS([1]销售表!$J:$J,[1]销售表!$I:$I,$A15,[1]销售表!$B:$B,AX$4),($L15-SUM($P15:AW15))*110%/(180-AW$4)) -> 0 | AY15: =IF($C15>AY$4,SUMIFS([1]销售表!$J:$J,[1]销售表!$I:$I,$A15,[1]销售表!$B:$B,AY$4),($L15-SUM($P15:AX15))*110%/(180-AX$4)) -> 0 | AZ15: =IF($C15>AZ$4,SUMIFS([1]销售表!$J:$J,[1]销售表!$I:$I,$A15,[1]销售表!$B:$B,AZ$4),($L15-SUM($P15:AY15))*110%/(180-AY$4)) -> 0 | BA15: =IF($C15>BA$4,SUMIFS([1]销售表!$J:$J,[1]销售表!$I:$I,$A15,[1]销售表!$B:$B,BA$4),($L15-SUM($P15:AZ15))*110%/(180-AZ$4)) -> 0 | ... EE15: =IF($C15>EE$4,SUMIFS([1]销售表!$J:$J,[1]销售表!$I:$I,$A15,[1]销售表!$B:$B,EE$4),($L15-SUM($P15:ED15))*110%/(180-ED$4)) -> 0 | EF15: =IF($C15>EF$4,SUMIFS([1]销售表!$J:$J,[1]销售表!$I:$I,$A15,[1]销售表!$B:$B,EF$4),($L15-SUM($P15:EE15))*100%/(180-EE$4)) -> 0 | EG15: =IF($C15>EG$4,SUMIFS([1]销售表!$J:$J,[1]销售表!$I:$I,$A15,[1]销售表!$B:$B,EG$4),($L15-SUM($P15:EF15))*100%/(180-EF$4)) -> 0 | EH15: =IF($C15>EH$4,SUMIFS([1]销售表!$J:$J,[1]销售表!$I:$I,$A15,[1]销售表!$B:$B,EH$4),($L15-SUM($P15:EG15))*100%/(180-EG$4)) -> 0 | EI15: =IF($C15>EI$4,SUMIFS([1]销售表!$J:$J,[1]销售表!$I:$I,$A15,[1]销售表!$B:$B,EI$4),($L15-SUM($P15:EH15))*100%/(180-EH$4)) -> 0 | EJ15: =IF($C15>EJ$4,SUMIFS([1]销售表!$J:$J,[1]销售表!$I:$I,$A15,[1]销售表!$B:$B,EJ$4),($L15-SUM($P15:EI15))*100%/(180-EI$4)) -> 0 | EK15: =IF($C15>EK$4,SUMIFS([1]销售表!$J:$J,[1]销售表!$I:$I,$A15,[1]销售表!$B:$B,EK$4),($L15-SUM($P15:EJ15))*100%/(180-EJ$4)) -> 0 | EL15: =IF($C15>EL$4,SUMIFS([1]销售表!$J:$J,[1]销售表!$I:$I,$A15,[1]销售表!$B:$B,EL$4),($L15-SUM($P15:EK15))*100%/(180-EK$4)) -> 0 | EM15: =IF($C15>EM$4,SUMIFS([1]销售表!$J:$J,[1]销售表!$I:$I,$A15,[1]销售表!$B:$B,EM$4),($L15-SUM($P15:EL15))*100%/(180-EL$4)) -> 0 | ... GM15: =IF($C15>GM$4,SUMIFS([1]销售表!$J:$J,[1]销售表!$I:$I,$A15,[1]销售表!$B:$B,GM$4),($L15-SUM($P15:GL15))*100%/(180-GL$4)) -> 0
C16: =TODAY()-B16 -> 46208 | E16: =L16-G16 -> 0 | H16: =G16/L16 -> #DIV/0! | J16: =SUMIFS([1]销售表!J:J,[1]销售表!I:I,A16,[1]销售表!E:E,"可取") -> 0 | M16: =_xlfn.XLOOKUP(A16,[1]销售表!I:I,[1]销售表!J:J,0,0,-1) -> 0 | N16: {=IF(C16>180,"0",INDEX(P16:GM16,C16))} -> 0 | P16: =SUMIFS([1]销售表!J:J,[1]销售表!I:I,A16,[1]销售表!B:B,$P$4) -> 0 | Q16: =IF($C16>Q$4,SUMIFS([1]销售表!$J:$J,[1]销售表!$I:$I,$A16,[1]销售表!$B:$B,Q$4),($L16-SUM($P16))*80%/(180-P$4)) -> 0 | R16: =IF($C16>R$4,SUMIFS([1]销售表!$J:$J,[1]销售表!$I:$I,$A16,[1]销售表!$B:$B,R$4),($L16-SUM($P16:Q16))*80%/(180-Q$4)) -> 0 | S16: =IF($C16>S$4,SUMIFS([1]销售表!$J:$J,[1]销售表!$I:$I,$A16,[1]销售表!$B:$B,S$4),($L16-SUM($P16:R16))*80%/(180-R$4)) -> 0 | T16: =IF($C16>T$4,SUMIFS([1]销售表!$J:$J,[1]销售表!$I:$I,$A16,[1]销售表!$B:$B,T$4),($L16-SUM($P16:S16))*80%/(180-S$4)) -> 0 | U16: =IF($C16>U$4,SUMIFS([1]销售表!$J:$J,[1]销售表!$I:$I,$A16,[1]销售表!$B:$B,U$4),($L16-SUM($P16:T16))*80%/(180-T$4)) -> 0 | V16: =IF($C16>V$4,SUMIFS([1]销售表!$J:$J,[1]销售表!$I:$I,$A16,[1]销售表!$B:$B,V$4),($L16-SUM($P16:U16))*80%/(180-U$4)) -> 0 | W16: =IF($C16>W$4,SUMIFS([1]销售表!$J:$J,[1]销售表!$I:$I,$A16,[1]销售表!$B:$B,W$4),($L16-SUM($P16:V16))*80%/(180-V$4)) -> 0 | X16: =IF($C16>X$4,SUMIFS([1]销售表!$J:$J,[1]销售表!$I:$I,$A16,[1]销售表!$B:$B,X$4),($L16-SUM($P16:W16))*80%/(180-W$4)) -> 0 | Y16: =IF($C16>Y$4,SUMIFS([1]销售表!$J:$J,[1]销售表!$I:$I,$A16,[1]销售表!$B:$B,Y$4),($L16-SUM($P16:X16))*80%/(180-X$4)) -> 0 | ... AS16: =IF($C16>AS$4,SUMIFS([1]销售表!$J:$J,[1]销售表!$I:$I,$A16,[1]销售表!$B:$B,AS$4),($L16-SUM($P16:AR16))*80%/(180-AR$4)) -> 0 | AT16: =IF($C16>AT$4,SUMIFS([1]销售表!$J:$J,[1]销售表!$I:$I,$A16,[1]销售表!$B:$B,AT$4),($L16-SUM($P16:AS16))*110%/(180-AS$4)) -> 0 | AU16: =IF($C16>AU$4,SUMIFS([1]销售表!$J:$J,[1]销售表!$I:$I,$A16,[1]销售表!$B:$B,AU$4),($L16-SUM($P16:AT16))*110%/(180-AT$4)) -> 0 | AV16: =IF($C16>AV$4,SUMIFS([1]销售表!$J:$J,[1]销售表!$I:$I,$A16,[1]销售表!$B:$B,AV$4),($L16-SUM($P16:AU16))*110%/(180-AU$4)) -> 0 | AW16: =IF($C16>AW$4,SUMIFS([1]销售表!$J:$J,[1]销售表!$I:$I,$A16,[1]销售表!$B:$B,AW$4),($L16-SUM($P16:AV16))*110%/(180-AV$4)) -> 0 | AX16: =IF($C16>AX$4,SUMIFS([1]销售表!$J:$J,[1]销售表!$I:$I,$A16,[1]销售表!$B:$B,AX$4),($L16-SUM($P16:AW16))*110%/(180-AW$4)) -> 0 | AY16: =IF($C16>AY$4,SUMIFS([1]销售表!$J:$J,[1]销售表!$I:$I,$A16,[1]销售表!$B:$B,AY$4),($L16-SUM($P16:AX16))*110%/(180-AX$4)) -> 0 | AZ16: =IF($C16>AZ$4,SUMIFS([1]销售表!$J:$J,[1]销售表!$I:$I,$A16,[1]销售表!$B:$B,AZ$4),($L16-SUM($P16:AY16))*110%/(180-AY$4)) -> 0 | BA16: =IF($C16>BA$4,SUMIFS([1]销售表!$J:$J,[1]销售表!$I:$I,$A16,[1]销售表!$B:$B,BA$4),($L16-SUM($P16:AZ16))*110%/(180-AZ$4)) -> 0 | ... EE16: =IF($C16>EE$4,SUMIFS([1]销售表!$J:$J,[1]销售表!$I:$I,$A16,[1]销售表!$B:$B,EE$4),($L16-SUM($P16:ED16))*110%/(180-ED$4)) -> 0 | EF16: =IF($C16>EF$4,SUMIFS([1]销售表!$J:$J,[1]销售表!$I:$I,$A16,[1]销售表!$B:$B,EF$4),($L16-SUM($P16:EE16))*100%/(180-EE$4)) -> 0 | EG16: =IF($C16>EG$4,SUMIFS([1]销售表!$J:$J,[1]销售表!$I:$I,$A16,[1]销售表!$B:$B,EG$4),($L16-SUM($P16:EF16))*100%/(180-EF$4)) -> 0 | EH16: =IF($C16>EH$4,SUMIFS([1]销售表!$J:$J,[1]销售表!$I:$I,$A16,[1]销售表!$B:$B,EH$4),($L16-SUM($P16:EG16))*100%/(180-EG$4)) -> 0 | EI16: =IF($C16>EI$4,SUMIFS([1]销售表!$J:$J,[1]销售表!$I:$I,$A16,[1]销售表!$B:$B,EI$4),($L16-SUM($P16:EH16))*100%/(180-EH$4)) -> 0 | EJ16: =IF($C16>EJ$4,SUMIFS([1]销售表!$J:$J,[1]销售表!$I:$I,$A16,[1]销售表!$B:$B,EJ$4),($L16-SUM($P16:EI16))*100%/(180-EI$4)) -> 0 | EK16: =IF($C16>EK$4,SUMIFS([1]销售表!$J:$J,[1]销售表!$I:$I,$A16,[1]销售表!$B:$B,EK$4),($L16-SUM($P16:EJ16))*100%/(180-EJ$4)) -> 0 | EL16: =IF($C16>EL$4,SUMIFS([1]销售表!$J:$J,[1]销售表!$I:$I,$A16,[1]销售表!$B:$B,EL$4),($L16-SUM($P16:EK16))*100%/(180-EK$4)) -> 0 | EM16: =IF($C16>EM$4,SUMIFS([1]销售表!$J:$J,[1]销售表!$I:$I,$A16,[1]销售表!$B:$B,EM$4),($L16-SUM($P16:EL16))*100%/(180-EL$4)) -> 0 | ... GM16: =IF($C16>GM$4,SUMIFS([1]销售表!$J:$J,[1]销售表!$I:$I,$A16,[1]销售表!$B:$B,GM$4),($L16-SUM($P16:GL16))*100%/(180-GL$4)) -> 0
C17: =TODAY()-B17 -> 46208 | E17: =L17-G17 -> 0 | H17: =G17/L17 -> #DIV/0! | J17: =SUMIFS([1]销售表!J:J,[1]销售表!I:I,A17,[1]销售表!E:E,"可取") -> 0 | M17: =_xlfn.XLOOKUP(A17,[1]销售表!I:I,[1]销售表!J:J,0,0,-1) -> 0 | N17: {=IF(C17>180,"0",INDEX(P17:GM17,C17))} -> 0 | P17: =SUMIFS([1]销售表!J:J,[1]销售表!I:I,A17,[1]销售表!B:B,$P$4) -> 0 | Q17: =IF($C17>Q$4,SUMIFS([1]销售表!$J:$J,[1]销售表!$I:$I,$A17,[1]销售表!$B:$B,Q$4),($L17-SUM($P17))*80%/(180-P$4)) -> 0 | R17: =IF($C17>R$4,SUMIFS([1]销售表!$J:$J,[1]销售表!$I:$I,$A17,[1]销售表!$B:$B,R$4),($L17-SUM($P17:Q17))*80%/(180-Q$4)) -> 0 | S17: =IF($C17>S$4,SUMIFS([1]销售表!$J:$J,[1]销售表!$I:$I,$A17,[1]销售表!$B:$B,S$4),($L17-SUM($P17:R17))*80%/(180-R$4)) -> 0 | T17: =IF($C17>T$4,SUMIFS([1]销售表!$J:$J,[1]销售表!$I:$I,$A17,[1]销售表!$B:$B,T$4),($L17-SUM($P17:S17))*80%/(180-S$4)) -> 0 | U17: =IF($C17>U$4,SUMIFS([1]销售表!$J:$J,[1]销售表!$I:$I,$A17,[1]销售表!$B:$B,U$4),($L17-SUM($P17:T17))*80%/(180-T$4)) -> 0 | V17: =IF($C17>V$4,SUMIFS([1]销售表!$J:$J,[1]销售表!$I:$I,$A17,[1]销售表!$B:$B,V$4),($L17-SUM($P17:U17))*80%/(180-U$4)) -> 0 | W17: =IF($C17>W$4,SUMIFS([1]销售表!$J:$J,[1]销售表!$I:$I,$A17,[1]销售表!$B:$B,W$4),($L17-SUM($P17:V17))*80%/(180-V$4)) -> 0 | X17: =IF($C17>X$4,SUMIFS([1]销售表!$J:$J,[1]销售表!$I:$I,$A17,[1]销售表!$B:$B,X$4),($L17-SUM($P17:W17))*80%/(180-W$4)) -> 0 | Y17: =IF($C17>Y$4,SUMIFS([1]销售表!$J:$J,[1]销售表!$I:$I,$A17,[1]销售表!$B:$B,Y$4),($L17-SUM($P17:X17))*80%/(180-X$4)) -> 0 | ... AS17: =IF($C17>AS$4,SUMIFS([1]销售表!$J:$J,[1]销售表!$I:$I,$A17,[1]销售表!$B:$B,AS$4),($L17-SUM($P17:AR17))*80%/(180-AR$4)) -> 0 | AT17: =IF($C17>AT$4,SUMIFS([1]销售表!$J:$J,[1]销售表!$I:$I,$A17,[1]销售表!$B:$B,AT$4),($L17-SUM($P17:AS17))*110%/(180-AS$4)) -> 0 | AU17: =IF($C17>AU$4,SUMIFS([1]销售表!$J:$J,[1]销售表!$I:$I,$A17,[1]销售表!$B:$B,AU$4),($L17-SUM($P17:AT17))*110%/(180-AT$4)) -> 0 | AV17: =IF($C17>AV$4,SUMIFS([1]销售表!$J:$J,[1]销售表!$I:$I,$A17,[1]销售表!$B:$B,AV$4),($L17-SUM($P17:AU17))*110%/(180-AU$4)) -> 0 | AW17: =IF($C17>AW$4,SUMIFS([1]销售表!$J:$J,[1]销售表!$I:$I,$A17,[1]销售表!$B:$B,AW$4),($L17-SUM($P17:AV17))*110%/(180-AV$4)) -> 0 | AX17: =IF($C17>AX$4,SUMIFS([1]销售表!$J:$J,[1]销售表!$I:$I,$A17,[1]销售表!$B:$B,AX$4),($L17-SUM($P17:AW17))*110%/(180-AW$4)) -> 0 | AY17: =IF($C17>AY$4,SUMIFS([1]销售表!$J:$J,[1]销售表!$I:$I,$A17,[1]销售表!$B:$B,AY$4),($L17-SUM($P17:AX17))*110%/(180-AX$4)) -> 0 | AZ17: =IF($C17>AZ$4,SUMIFS([1]销售表!$J:$J,[1]销售表!$I:$I,$A17,[1]销售表!$B:$B,AZ$4),($L17-SUM($P17:AY17))*110%/(180-AY$4)) -> 0 | BA17: =IF($C17>BA$4,SUMIFS([1]销售表!$J:$J,[1]销售表!$I:$I,$A17,[1]销售表!$B:$B,BA$4),($L17-SUM($P17:AZ17))*110%/(180-AZ$4)) -> 0 | ... EE17: =IF($C17>EE$4,SUMIFS([1]销售表!$J:$J,[1]销售表!$I:$I,$A17,[1]销售表!$B:$B,EE$4),($L17-SUM($P17:ED17))*110%/(180-ED$4)) -> 0 | EF17: =IF($C17>EF$4,SUMIFS([1]销售表!$J:$J,[1]销售表!$I:$I,$A17,[1]销售表!$B:$B,EF$4),($L17-SUM($P17:EE17))*100%/(180-EE$4)) -> 0 | EG17: =IF($C17>EG$4,SUMIFS([1]销售表!$J:$J,[1]销售表!$I:$I,$A17,[1]销售表!$B:$B,EG$4),($L17-SUM($P17:EF17))*100%/(180-EF$4)) -> 0 | EH17: =IF($C17>EH$4,SUMIFS([1]销售表!$J:$J,[1]销售表!$I:$I,$A17,[1]销售表!$B:$B,EH$4),($L17-SUM($P17:EG17))*100%/(180-EG$4)) -> 0 | EI17: =IF($C17>EI$4,SUMIFS([1]销售表!$J:$J,[1]销售表!$I:$I,$A17,[1]销售表!$B:$B,EI$4),($L17-SUM($P17:EH17))*100%/(180-EH$4)) -> 0 | EJ17: =IF($C17>EJ$4,SUMIFS([1]销售表!$J:$J,[1]销售表!$I:$I,$A17,[1]销售表!$B:$B,EJ$4),($L17-SUM($P17:EI17))*100%/(180-EI$4)) -> 0 | EK17: =IF($C17>EK$4,SUMIFS([1]销售表!$J:$J,[1]销售表!$I:$I,$A17,[1]销售表!$B:$B,EK$4),($L17-SUM($P17:EJ17))*100%/(180-EJ$4)) -> 0 | EL17: =IF($C17>EL$4,SUMIFS([1]销售表!$J:$J,[1]销售表!$I:$I,$A17,[1]销售表!$B:$B,EL$4),($L17-SUM($P17:EK17))*100%/(180-EK$4)) -> 0 | EM17: =IF($C17>EM$4,SUMIFS([1]销售表!$J:$J,[1]销售表!$I:$I,$A17,[1]销售表!$B:$B,EM$4),($L17-SUM($P17:EL17))*100%/(180-EL$4)) -> 0 | ... GM17: =IF($C17>GM$4,SUMIFS([1]销售表!$J:$J,[1]销售表!$I:$I,$A17,[1]销售表!$B:$B,GM$4),($L17-SUM($P17:GL17))*100%/(180-GL$4)) -> 0
